Workbook

Sheet Overview
C1: 0
B2: =Stats!B5 -> Continue on: | C2: =Stats!C5 -> 45473
O3: (across all courses)
A5: No | B5: Course | C5: TUD College | D5: Area | E5: Topic | F5: Concept | G5: PIRA1 | H5: PIRA2 | I5: PIRA3 Coding | J5: PIRA4 Coding | K5: Instructor | L5: Instructor | M5: Date | N5: Demo | O5: Occurences | P5: Website | Q5: Description | R5: =Demos!H3 -> Video recording | S5: Note | T5: Demonstrated [Y/N] | U5: Video Recorded [Y/N] | V5: Tables per demo | W5: Tables per week
A6: =ROW()-5 -> 1 | B6: Matching Day | C6: =IFERROR(VLOOKUP(B6, Courses!$C$3:$E$836, 2, FALSE),"") -> Matching Day | D6: =IFERROR(VLOOKUP(MID(G6,1,1), PIRA!$B$1:$E$1146, 2, FALSE),"") -> 1 Mechanics | E6: =IFERROR(VLOOKUP(MID(G6,1,2),PIRA!$B$1:$E$1144,2,FALSE),"")&" "&IFERROR(VLOOKUP(MID(H6,1,2),PIRA!$B$1:$E$1144,2,FALSE),"")&" "&IFERROR(VLOOKUP(MID(I6,1,2),PIRA!$B$1:$E$1144,2,FALSE),"") -> Rotational Dynamics | F6: =IFERROR(VLOOKUP(MID(G6,1,4),PIRA!$B$1:$E$1144,2,FALSE),"")&" "&IFERROR(VLOOKUP(MID(H6,1,4),PIRA!$B$1:$E$1144,2,FALSE),"")&" "&IFERROR(VLOOKUP(MID(I6,1,4),PIRA!$B$1:$E$1144,2,FALSE),"") -> Gyros | G6: 1Q50.04 | H6: =IFERROR(IF(VLOOKUP(G6,Demos!$B$3:$K$1368,2,FALSE)=0,"",VLOOKUP(G6,Demos!$B$3:$K$1368,2,FALSE)),"") | I6: =IFERROR(IF(VLOOKUP(G6,Demos!$B$3:$K$1368,3,FALSE)=0,"",VLOOKUP(G6,Demos!$B$3:$K$1368,3,FALSE)),"") | J6: =IFERROR(IF(VLOOKUP(G6,Demos!$B$3:$K$1368,4,FALSE)=0,"",VLOOKUP(G6,Demos!$B$3:$K$1368,4,FALSE)),"") | K6: Koen van Dongen | L6: Ron Haaksman | M6: 45473 | N6: =IFERROR(VLOOKUP(G6,Demos!$B$3:$K$1368,5,FALSE),"") -> Precession (2) | O6: =IF(N6="","",COUNTIF($N$6:N2125, N6)) -> 62 | P6: =IFERROR(IF(VLOOKUP(G6,Demos!$B$3:$K$1368,6,FALSE)=0,"",VLOOKUP(G6,Demos!$B$3:$K$1368,6,FALSE)),"") -> www.de-monstrare.nl/pdf/Precession%20_2_.pdf | Q6: =IFERROR(IF(VLOOKUP(G6,Demos!$B$3:$K$1368,8,FALSE)=0,"",VLOOKUP(G6,Demos!$B$3:$K$1368,8,FALSE)),"") | R6: =IFERROR(IF(VLOOKUP(G6,Demos!$B$3:$K$1368,7,FALSE)=0,"",VLOOKUP(G6,Demos!$B$3:$K$1368,7,FALSE)),"") | U6: =IFERROR(VLOOKUP(G6,Demos!$B$7:N6043,12,FALSE),"")
A7: =ROW()-5 -> 2 | B7: TN2785 | C7: =IFERROR(VLOOKUP(B7, Courses!$C$3:$E$836, 2, FALSE),"") -> Physical Transport Phenomena | D7: =IFERROR(VLOOKUP(MID(G7,1,1), PIRA!$B$1:$E$1146, 2, FALSE),"") -> 2 Fluid Mechanics | E7: =IFERROR(VLOOKUP(MID(G7,1,2),PIRA!$B$1:$E$1144,2,FALSE),"")&" "&IFERROR(VLOOKUP(MID(H7,1,2),PIRA!$B$1:$E$1144,2,FALSE),"")&" "&IFERROR(VLOOKUP(MID(I7,1,2),PIRA!$B$1:$E$1144,2,FALSE),"") -> Dynamics of Fluids | F7: =IFERROR(VLOOKUP(MID(G7,1,4),PIRA!$B$1:$E$1144,2,FALSE),"")&" "&IFERROR(VLOOKUP(MID(H7,1,4),PIRA!$B$1:$E$1144,2,FALSE),"")&" "&IFERROR(VLOOKUP(MID(I7,1,4),PIRA!$B$1:$E$1144,2,FALSE),"") -> Non Newtonian Fluids | G7: 2C60.30 | H7: =IFERROR(IF(VLOOKUP(G7,Demos!$B$3:$K$1368,2,FALSE)=0,"",VLOOKUP(G7,Demos!$B$3:$K$1368,2,FALSE)),"") | I7: =IFERROR(IF(VLOOKUP(G7,Demos!$B$3:$K$1368,3,FALSE)=0,"",VLOOKUP(G7,Demos!$B$3:$K$1368,3,FALSE)),"") | J7: =IFERROR(IF(VLOOKUP(G7,Demos!$B$3:$K$1368,4,FALSE)=0,"",VLOOKUP(G7,Demos!$B$3:$K$1368,4,FALSE)),"") | K7: Martin Rohde | M7: 45463 | N7: =IFERROR(VLOOKUP(G7,Demos!$B$3:$K$1368,5,FALSE),"") -> Cornstarch | O7: =IF(N7="","",COUNTIF($N$6:N2126, N7)) -> 7 | P7: =IFERROR(IF(VLOOKUP(G7,Demos!$B$3:$K$1368,6,FALSE)=0,"",VLOOKUP(G7,Demos!$B$3:$K$1368,6,FALSE)),"") -> N/A | Q7: =IFERROR(IF(VLOOKUP(G7,Demos!$B$3:$K$1368,8,FALSE)=0,"",VLOOKUP(G7,Demos!$B$3:$K$1368,8,FALSE)),"") -> Cornstarch mixed with water, punch it, throw a metal ball in it from a height, or just slowely place the sphere on the surface. | R7: =IFERROR(IF(VLOOKUP(G7,Demos!$B$3:$K$1368,7,FALSE)=0,"",VLOOKUP(G7,Demos!$B$3:$K$1368,7,FALSE)),"") -> See 2021 Zoomopname "Recording (1).mp4" that is "opname hoorcollege 19.mp4" from 01:07 and Collegerama recording 2011/2012 - https://collegerama.tudelft.nl/Mediasite/Channel/as-bsc-tn/watch/ and 20June 2023 "TN2786_020" recording from 00:18:48 on https://collegeramavideoportal.tudelft.nl/catalogue/tn2786/presentation/68504749c58049f6866eec6f346bbda21d?academicYear=2022-2023-tn2786 | U7: =IFERROR(VLOOKUP(G7,Demos!$B$7:N5904,12,FALSE),"") -> 0
A8: =ROW()-5 -> 3 | B8: TN2054 | C8: =IFERROR(VLOOKUP(B8, Courses!$C$3:$E$836, 2, FALSE),"") -> Electromagnetism | D8: =IFERROR(VLOOKUP(MID(G8,1,1), PIRA!$B$1:$E$1146, 2, FALSE),"") -> 5 Electricity and Magnetism | E8: =IFERROR(VLOOKUP(MID(G8,1,2),PIRA!$B$1:$E$1144,2,FALSE),"")&" "&IFERROR(VLOOKUP(MID(H8,1,2),PIRA!$B$1:$E$1144,2,FALSE),"")&" "&IFERROR(VLOOKUP(MID(I8,1,2),PIRA!$B$1:$E$1144,2,FALSE),"") -> AC Circuits Magnetic Fields and Forces | F8: =IFERROR(VLOOKUP(MID(G8,1,4),PIRA!$B$1:$E$1144,2,FALSE),"")&" "&IFERROR(VLOOKUP(MID(H8,1,4),PIRA!$B$1:$E$1144,2,FALSE),"")&" "&IFERROR(VLOOKUP(MID(I8,1,4),PIRA!$B$1:$E$1144,2,FALSE),"") -> Impedance Magnetic Fields | G8: 5L10.41 | H8: =IFERROR(IF(VLOOKUP(G8,Demos!$B$3:$K$1368,2,FALSE)=0,"",VLOOKUP(G8,Demos!$B$3:$K$1368,2,FALSE)),"") -> 5H10.61 | I8: =IFERROR(IF(VLOOKUP(G8,Demos!$B$3:$K$1368,3,FALSE)=0,"",VLOOKUP(G8,Demos!$B$3:$K$1368,3,FALSE)),"") | J8: =IFERROR(IF(VLOOKUP(G8,Demos!$B$3:$K$1368,4,FALSE)=0,"",VLOOKUP(G8,Demos!$B$3:$K$1368,4,FALSE)),"") | K8: Jeroen Kalkman | L8: Niels van Dijk | M8: 45462 | N8: =IFERROR(VLOOKUP(G8,Demos!$B$3:$K$1368,5,FALSE),"") -> Skin Effect | O8: =IF(N8="","",COUNTIF($N$6:N2127, N8)) -> 5 | P8: =IFERROR(IF(VLOOKUP(G8,Demos!$B$3:$K$1368,6,FALSE)=0,"",VLOOKUP(G8,Demos!$B$3:$K$1368,6,FALSE)),"") -> N/A | Q8: =IFERROR(IF(VLOOKUP(G8,Demos!$B$3:$K$1368,8,FALSE)=0,"",VLOOKUP(G8,Demos!$B$3:$K$1368,8,FALSE)),"") -> Still have to device a demonstration setup (12-Sep-13) | R8: =IFERROR(IF(VLOOKUP(G8,Demos!$B$3:$K$1368,7,FALSE)=0,"",VLOOKUP(G8,Demos!$B$3:$K$1368,7,FALSE)),"") | U8: =IFERROR(VLOOKUP(G8,Demos!$B$7:N5907,12,FALSE),"")
A9: =ROW()-5 -> 4 | B9: TN2785 | C9: =IFERROR(VLOOKUP(B9, Courses!$C$3:$E$836, 2, FALSE),"") -> Physical Transport Phenomena | D9: =IFERROR(VLOOKUP(MID(G9,1,1), PIRA!$B$1:$E$1146, 2, FALSE),"") -> 4 Thermodynamics | E9: =IFERROR(VLOOKUP(MID(G9,1,2),PIRA!$B$1:$E$1144,2,FALSE),"")&" "&IFERROR(VLOOKUP(MID(H9,1,2),PIRA!$B$1:$E$1144,2,FALSE),"")&" "&IFERROR(VLOOKUP(MID(I9,1,2),PIRA!$B$1:$E$1144,2,FALSE),"") -> Entropy and the Second Law | F9: =IFERROR(VLOOKUP(MID(G9,1,4),PIRA!$B$1:$E$1144,2,FALSE),"")&" "&IFERROR(VLOOKUP(MID(H9,1,4),PIRA!$B$1:$E$1144,2,FALSE),"")&" "&IFERROR(VLOOKUP(MID(I9,1,4),PIRA!$B$1:$E$1144,2,FALSE),"") -> Entropy | G9: 4F10.03 | H9: =IFERROR(IF(VLOOKUP(G9,Demos!$B$3:$K$1368,2,FALSE)=0,"",VLOOKUP(G9,Demos!$B$3:$K$1368,2,FALSE)),"") | I9: =IFERROR(IF(VLOOKUP(G9,Demos!$B$3:$K$1368,3,FALSE)=0,"",VLOOKUP(G9,Demos!$B$3:$K$1368,3,FALSE)),"") | J9: =IFERROR(IF(VLOOKUP(G9,Demos!$B$3:$K$1368,4,FALSE)=0,"",VLOOKUP(G9,Demos!$B$3:$K$1368,4,FALSE)),"") | K9: Martin Rohde | M9: 45459 | N9: =IFERROR(VLOOKUP(G9,Demos!$B$3:$K$1368,5,FALSE),"") -> Violation of the Entropy Law? | O9: =IF(N9="","",COUNTIF($N$6:N2128, N9)) -> 10 | P9: =IFERROR(IF(VLOOKUP(G9,Demos!$B$3:$K$1368,6,FALSE)=0,"",VLOOKUP(G9,Demos!$B$3:$K$1368,6,FALSE)),"") -> http://www.de-monstrare.nl/pdf/Violation%20of%20the%20entropy%20law.pdf | Q9: =IFERROR(IF(VLOOKUP(G9,Demos!$B$3:$K$1368,8,FALSE)=0,"",VLOOKUP(G9,Demos!$B$3:$K$1368,8,FALSE)),"") | R9: =IFERROR(IF(VLOOKUP(G9,Demos!$B$3:$K$1368,7,FALSE)=0,"",VLOOKUP(G9,Demos!$B$3:$K$1368,7,FALSE)),"") -> See 2021 Zoomopname "Recording1.mp4" that is "opname hoorcollege 18.mp4" from 01:18:01 and Collegerama recording 2011/2012 - https://collegerama.tudelft.nl/Mediasite/Channel/as-bsc-tn/watch/b6b2331bc2144aba9c70d01fb3cfa6311d and 16 June 2023 "TN2786_019" recording from 00:05:40 on https://collegeramavideoportal.tudelft.nl/catalogue/tn2786/presentation/b21269167c454661aa9f66f4762bcfda1d?academicYear=2022-2023-tn2786 | U9: =IFERROR(VLOOKUP(G9,Demos!$B$7:N5906,12,FALSE),"")
A10: =ROW()-5 -> 5 | B10: TN2785 | C10: =IFERROR(VLOOKUP(B10, Courses!$C$3:$E$836, 2, FALSE),"") -> Physical Transport Phenomena | D10: =IFERROR(VLOOKUP(MID(G10,1,1), PIRA!$B$1:$E$1146, 2, FALSE),"") -> 2 Fluid Mechanics | E10: =IFERROR(VLOOKUP(MID(G10,1,2),PIRA!$B$1:$E$1144,2,FALSE),"")&" "&IFERROR(VLOOKUP(MID(H10,1,2),PIRA!$B$1:$E$1144,2,FALSE),"")&" "&IFERROR(VLOOKUP(MID(I10,1,2),PIRA!$B$1:$E$1144,2,FALSE),"") -> Dynamics of Fluids | F10: =IFERROR(VLOOKUP(MID(G10,1,4),PIRA!$B$1:$E$1144,2,FALSE),"")&" "&IFERROR(VLOOKUP(MID(H10,1,4),PIRA!$B$1:$E$1144,2,FALSE),"")&" "&IFERROR(VLOOKUP(MID(I10,1,4),PIRA!$B$1:$E$1144,2,FALSE),"") -> Flow Rate | G10: 2C10.10 | H10: =IFERROR(IF(VLOOKUP(G10,Demos!$B$3:$K$1368,2,FALSE)=0,"",VLOOKUP(G10,Demos!$B$3:$K$1368,2,FALSE)),"") | I10: =IFERROR(IF(VLOOKUP(G10,Demos!$B$3:$K$1368,3,FALSE)=0,"",VLOOKUP(G10,Demos!$B$3:$K$1368,3,FALSE)),"") | J10: =IFERROR(IF(VLOOKUP(G10,Demos!$B$3:$K$1368,4,FALSE)=0,"",VLOOKUP(G10,Demos!$B$3:$K$1368,4,FALSE)),"") | K10: Martin Rohde | M10: 45457 | N10: =IFERROR(VLOOKUP(G10,Demos!$B$3:$K$1368,5,FALSE),"") -> Draining time of a water container through a long and short hose | O10: =IF(N10="","",COUNTIF($N$6:N2129, N10)) -> 7 | P10: =IFERROR(IF(VLOOKUP(G10,Demos!$B$3:$K$1368,6,FALSE)=0,"",VLOOKUP(G10,Demos!$B$3:$K$1368,6,FALSE)),"") -> N/A | Q10: =IFERROR(IF(VLOOKUP(G10,Demos!$B$3:$K$1368,8,FALSE)=0,"",VLOOKUP(G10,Demos!$B$3:$K$1368,8,FALSE)),"") | R10: =IFERROR(IF(VLOOKUP(G10,Demos!$B$3:$K$1368,7,FALSE)=0,"",VLOOKUP(G10,Demos!$B$3:$K$1368,7,FALSE)),"") -> See 2021 Zoomopname "Recording.mp4", that is "opname hoorcollege 17.mp4" and Collegerama recording 2011/2012 - https://collegerama.tudelft.nl/Mediasite/Channel/as-bsc-tn/watch/b6b2331bc2144aba9c70d01fb3cfa6311d and 14 June 2023 recording "TN2786_018" from 01:01:30 up until 01:21:00 https://collegeramavideoportal.tudelft.nl/catalogue/tn2786/presentation/20fe5ac00eb6426484f37c124af17dd31d?academicYear=2022-2023-tn2786 | T10: Yes (myself) | U10: =IFERROR(VLOOKUP(G10,Demos!$B$7:N5908,12,FALSE),"") -> 0
A11: =ROW()-5 -> 6 | B11: TN2054 | C11: =IFERROR(VLOOKUP(B11, Courses!$C$3:$E$836, 2, FALSE),"") -> Electromagnetism | D11: =IFERROR(VLOOKUP(MID(G11,1,1), PIRA!$B$1:$E$1146, 2, FALSE),"") -> 5 Electricity and Magnetism | E11: =IFERROR(VLOOKUP(MID(G11,1,2),PIRA!$B$1:$E$1144,2,FALSE),"")&" "&IFERROR(VLOOKUP(MID(H11,1,2),PIRA!$B$1:$E$1144,2,FALSE),"")&" "&IFERROR(VLOOKUP(MID(I11,1,2),PIRA!$B$1:$E$1144,2,FALSE),"") -> Electromagnetic Radiation | F11: =IFERROR(VLOOKUP(MID(G11,1,4),PIRA!$B$1:$E$1144,2,FALSE),"")&" "&IFERROR(VLOOKUP(MID(H11,1,4),PIRA!$B$1:$E$1144,2,FALSE),"")&" "&IFERROR(VLOOKUP(MID(I11,1,4),PIRA!$B$1:$E$1144,2,FALSE),"") -> Transmission Lines and Antennas | G11: 5N10.50 | H11: =IFERROR(IF(VLOOKUP(G11,Demos!$B$3:$K$1368,2,FALSE)=0,"",VLOOKUP(G11,Demos!$B$3:$K$1368,2,FALSE)),"") | I11: =IFERROR(IF(VLOOKUP(G11,Demos!$B$3:$K$1368,3,FALSE)=0,"",VLOOKUP(G11,Demos!$B$3:$K$1368,3,FALSE)),"") | J11: =IFERROR(IF(VLOOKUP(G11,Demos!$B$3:$K$1368,4,FALSE)=0,"",VLOOKUP(G11,Demos!$B$3:$K$1368,4,FALSE)),"") | K11: Jeroen Kalkman | L11: Niels van Dijk | M11: 45457 | N11: =IFERROR(VLOOKUP(G11,Demos!$B$3:$K$1368,5,FALSE),"") -> Electromagnetic Waves (Lecher Lines) | O11: =IF(N11="","",COUNTIF($N$6:N2130, N11)) -> 15 | P11: =IFERROR(IF(VLOOKUP(G11,Demos!$B$3:$K$1368,6,FALSE)=0,"",VLOOKUP(G11,Demos!$B$3:$K$1368,6,FALSE)),"") -> www.de-monstrare.nl/pdf/electromagnetic%20waves.pdf | Q11: =IFERROR(IF(VLOOKUP(G11,Demos!$B$3:$K$1368,8,FALSE)=0,"",VLOOKUP(G11,Demos!$B$3:$K$1368,8,FALSE)),"") -> Reflection, transmission, absorption, polarisation | R11: =IFERROR(IF(VLOOKUP(G11,Demos!$B$3:$K$1368,7,FALSE)=0,"",VLOOKUP(G11,Demos!$B$3:$K$1368,7,FALSE)),"") | T11: No (lecturer decided not to use demo) | U11: =IFERROR(VLOOKUP(G11,Demos!$B$7:N5905,12,FALSE),"")
A12: =ROW()-5 -> 7 | B12: TN2054 | C12: =IFERROR(VLOOKUP(B12, Courses!$C$3:$E$836, 2, FALSE),"") -> Electromagnetism | D12: =IFERROR(VLOOKUP(MID(G12,1,1), PIRA!$B$1:$E$1146, 2, FALSE),"") -> 5 Electricity and Magnetism | E12: =IFERROR(VLOOKUP(MID(G12,1,2),PIRA!$B$1:$E$1144,2,FALSE),"")&" "&IFERROR(VLOOKUP(MID(H12,1,2),PIRA!$B$1:$E$1144,2,FALSE),"")&" "&IFERROR(VLOOKUP(MID(I12,1,2),PIRA!$B$1:$E$1144,2,FALSE),"") -> Capacitance | F12: =IFERROR(VLOOKUP(MID(G12,1,4),PIRA!$B$1:$E$1144,2,FALSE),"")&" "&IFERROR(VLOOKUP(MID(H12,1,4),PIRA!$B$1:$E$1144,2,FALSE),"")&" "&IFERROR(VLOOKUP(MID(I12,1,4),PIRA!$B$1:$E$1144,2,FALSE),"") -> Dielectric | G12: 5C20.60 | H12: =IFERROR(IF(VLOOKUP(G12,Demos!$B$3:$K$1368,2,FALSE)=0,"",VLOOKUP(G12,Demos!$B$3:$K$1368,2,FALSE)),"") | I12: =IFERROR(IF(VLOOKUP(G12,Demos!$B$3:$K$1368,3,FALSE)=0,"",VLOOKUP(G12,Demos!$B$3:$K$1368,3,FALSE)),"") | J12: =IFERROR(IF(VLOOKUP(G12,Demos!$B$3:$K$1368,4,FALSE)=0,"",VLOOKUP(G12,Demos!$B$3:$K$1368,4,FALSE)),"") | K12: Jeroen Kalkman | L12: Martin Verweij | M12: 45456 | N12: =IFERROR(VLOOKUP(G12,Demos!$B$3:$K$1368,5,FALSE),"") -> Displacement Current | O12: =IF(N12="","",COUNTIF($N$6:N2131, N12)) -> 3 | P12: =IFERROR(IF(VLOOKUP(G12,Demos!$B$3:$K$1368,6,FALSE)=0,"",VLOOKUP(G12,Demos!$B$3:$K$1368,6,FALSE)),"") -> N/A | Q12: =IFERROR(IF(VLOOKUP(G12,Demos!$B$3:$K$1368,8,FALSE)=0,"",VLOOKUP(G12,Demos!$B$3:$K$1368,8,FALSE)),"") -> No demo available (pickup coil between capacitor plates w a periodic voltage applied to the cap.) | R12: =IFERROR(IF(VLOOKUP(G12,Demos!$B$3:$K$1368,7,FALSE)=0,"",VLOOKUP(G12,Demos!$B$3:$K$1368,7,FALSE)),"") | T12: No (no setup available yet) | U12: =IFERROR(VLOOKUP(G12,Demos!$B$7:N5880,12,FALSE),"")
A13: =ROW()-5 -> 8 | B13: Open Days | C13: =IFERROR(VLOOKUP(B13, Courses!$C$3:$E$836, 2, FALSE),"") -> Open Days | D13: =IFERROR(VLOOKUP(MID(G13,1,1), PIRA!$B$1:$E$1146, 2, FALSE),"") -> 3 Oscillations and Waves | E13: =IFERROR(VLOOKUP(MID(G13,1,2),PIRA!$B$1:$E$1144,2,FALSE),"")&" "&IFERROR(VLOOKUP(MID(H13,1,2),PIRA!$B$1:$E$1144,2,FALSE),"")&" "&IFERROR(VLOOKUP(MID(I13,1,2),PIRA!$B$1:$E$1144,2,FALSE),"") -> Oscillations | F13: =IFERROR(VLOOKUP(MID(G13,1,4),PIRA!$B$1:$E$1144,2,FALSE),"")&" "&IFERROR(VLOOKUP(MID(H13,1,4),PIRA!$B$1:$E$1144,2,FALSE),"")&" "&IFERROR(VLOOKUP(MID(I13,1,4),PIRA!$B$1:$E$1144,2,FALSE),"") -> Simple Harmonic Motion | G13: 3A40.01 | H13: =IFERROR(IF(VLOOKUP(G13,Demos!$B$3:$K$1368,2,FALSE)=0,"",VLOOKUP(G13,Demos!$B$3:$K$1368,2,FALSE)),"") | I13: =IFERROR(IF(VLOOKUP(G13,Demos!$B$3:$K$1368,3,FALSE)=0,"",VLOOKUP(G13,Demos!$B$3:$K$1368,3,FALSE)),"") | J13: =IFERROR(IF(VLOOKUP(G13,Demos!$B$3:$K$1368,4,FALSE)=0,"",VLOOKUP(G13,Demos!$B$3:$K$1368,4,FALSE)),"") | K13: Bart van den Dries | M13: 45454 | N13: =IFERROR(VLOOKUP(G13,Demos!$B$3:$K$1368,5,FALSE),"") -> Simple Harmonic Motion (SHM) (3) | O13: =IF(N13="","",COUNTIF($N$6:N2132, N13)) -> 12 | P13: =IFERROR(IF(VLOOKUP(G13,Demos!$B$3:$K$1368,6,FALSE)=0,"",VLOOKUP(G13,Demos!$B$3:$K$1368,6,FALSE)),"") -> www.de-monstrare.nl/pdf/Simple%20harmonic%20motion%20_SHM_%20_3_.pdf | Q13: =IFERROR(IF(VLOOKUP(G13,Demos!$B$3:$K$1368,8,FALSE)=0,"",VLOOKUP(G13,Demos!$B$3:$K$1368,8,FALSE)),"") | R13: =IFERROR(IF(VLOOKUP(G13,Demos!$B$3:$K$1368,7,FALSE)=0,"",VLOOKUP(G13,Demos!$B$3:$K$1368,7,FALSE)),"") | U13: =IFERROR(VLOOKUP(G13,Demos!$B$7:N5909,12,FALSE),"")
A14: =ROW()-5 -> 9 | B14: Matching Day | C14: =IFERROR(VLOOKUP(B14, Courses!$C$3:$E$836, 2, FALSE),"") -> Matching Day | D14: =IFERROR(VLOOKUP(MID(G14,1,1), PIRA!$B$1:$E$1146, 2, FALSE),"") -> 1 Mechanics | E14: =IFERROR(VLOOKUP(MID(G14,1,2),PIRA!$B$1:$E$1144,2,FALSE),"")&" "&IFERROR(VLOOKUP(MID(H14,1,2),PIRA!$B$1:$E$1144,2,FALSE),"")&" "&IFERROR(VLOOKUP(MID(I14,1,2),PIRA!$B$1:$E$1144,2,FALSE),"") -> Rotational Dynamics | F14: =IFERROR(VLOOKUP(MID(G14,1,4),PIRA!$B$1:$E$1144,2,FALSE),"")&" "&IFERROR(VLOOKUP(MID(H14,1,4),PIRA!$B$1:$E$1144,2,FALSE),"")&" "&IFERROR(VLOOKUP(MID(I14,1,4),PIRA!$B$1:$E$1144,2,FALSE),"") -> Gyros | G14: 1Q50.04 | H14: =IFERROR(IF(VLOOKUP(G14,Demos!$B$3:$K$1368,2,FALSE)=0,"",VLOOKUP(G14,Demos!$B$3:$K$1368,2,FALSE)),"") | I14: =IFERROR(IF(VLOOKUP(G14,Demos!$B$3:$K$1368,3,FALSE)=0,"",VLOOKUP(G14,Demos!$B$3:$K$1368,3,FALSE)),"") | J14: =IFERROR(IF(VLOOKUP(G14,Demos!$B$3:$K$1368,4,FALSE)=0,"",VLOOKUP(G14,Demos!$B$3:$K$1368,4,FALSE)),"") | K14: Wim Bouwman | L14: Ron Haaksman | M14: 45445 | N14: =IFERROR(VLOOKUP(G14,Demos!$B$3:$K$1368,5,FALSE),"") -> Precession (2) | O14: =IF(N14="","",COUNTIF($N$6:N2133, N14)) -> 62 | P14: =IFERROR(IF(VLOOKUP(G14,Demos!$B$3:$K$1368,6,FALSE)=0,"",VLOOKUP(G14,Demos!$B$3:$K$1368,6,FALSE)),"") -> www.de-monstrare.nl/pdf/Precession%20_2_.pdf | Q14: =IFERROR(IF(VLOOKUP(G14,Demos!$B$3:$K$1368,8,FALSE)=0,"",VLOOKUP(G14,Demos!$B$3:$K$1368,8,FALSE)),"") | R14: =IFERROR(IF(VLOOKUP(G14,Demos!$B$3:$K$1368,7,FALSE)=0,"",VLOOKUP(G14,Demos!$B$3:$K$1368,7,FALSE)),"") | U14: =IFERROR(VLOOKUP(G14,Demos!$B$7:N6044,12,FALSE),"")
A15: =ROW()-5 -> 10 | B15: Matching Day | C15: =IFERROR(VLOOKUP(B15, Courses!$C$3:$E$836, 2, FALSE),"") -> Matching Day | D15: =IFERROR(VLOOKUP(MID(G15,1,1), PIRA!$B$1:$E$1146, 2, FALSE),"") -> 1 Mechanics | E15: =IFERROR(VLOOKUP(MID(G15,1,2),PIRA!$B$1:$E$1144,2,FALSE),"")&" "&IFERROR(VLOOKUP(MID(H15,1,2),PIRA!$B$1:$E$1144,2,FALSE),"")&" "&IFERROR(VLOOKUP(MID(I15,1,2),PIRA!$B$1:$E$1144,2,FALSE),"") -> Rotational Dynamics | F15: =IFERROR(VLOOKUP(MID(G15,1,4),PIRA!$B$1:$E$1144,2,FALSE),"")&" "&IFERROR(VLOOKUP(MID(H15,1,4),PIRA!$B$1:$E$1144,2,FALSE),"")&" "&IFERROR(VLOOKUP(MID(I15,1,4),PIRA!$B$1:$E$1144,2,FALSE),"") -> Gyros | G15: 1Q50.04 | H15: =IFERROR(IF(VLOOKUP(G15,Demos!$B$3:$K$1368,2,FALSE)=0,"",VLOOKUP(G15,Demos!$B$3:$K$1368,2,FALSE)),"") | I15: =IFERROR(IF(VLOOKUP(G15,Demos!$B$3:$K$1368,3,FALSE)=0,"",VLOOKUP(G15,Demos!$B$3:$K$1368,3,FALSE)),"") | J15: =IFERROR(IF(VLOOKUP(G15,Demos!$B$3:$K$1368,4,FALSE)=0,"",VLOOKUP(G15,Demos!$B$3:$K$1368,4,FALSE)),"") | K15: Wim Bouwman | L15: Ron Haaksman | M15: 45445 | N15: =IFERROR(VLOOKUP(G15,Demos!$B$3:$K$1368,5,FALSE),"") -> Precession (2) | O15: =IF(N15="","",COUNTIF($N$6:N2134, N15)) -> 62 | P15: =IFERROR(IF(VLOOKUP(G15,Demos!$B$3:$K$1368,6,FALSE)=0,"",VLOOKUP(G15,Demos!$B$3:$K$1368,6,FALSE)),"") -> www.de-monstrare.nl/pdf/Precession%20_2_.pdf | Q15: =IFERROR(IF(VLOOKUP(G15,Demos!$B$3:$K$1368,8,FALSE)=0,"",VLOOKUP(G15,Demos!$B$3:$K$1368,8,FALSE)),"") | R15: =IFERROR(IF(VLOOKUP(G15,Demos!$B$3:$K$1368,7,FALSE)=0,"",VLOOKUP(G15,Demos!$B$3:$K$1368,7,FALSE)),"") | U15: =IFERROR(VLOOKUP(G15,Demos!$B$7:N5928,12,FALSE),"")
A16: =ROW()-5 -> 11 | B16: TN1201 | C16: =IFERROR(VLOOKUP(B16, Courses!$C$3:$E$836, 2, FALSE),"") -> Thermodynamics | D16: =IFERROR(VLOOKUP(MID(G16,1,1), PIRA!$B$1:$E$1146, 2, FALSE),"") -> 4 Thermodynamics | E16: =IFERROR(VLOOKUP(MID(G16,1,2),PIRA!$B$1:$E$1144,2,FALSE),"")&" "&IFERROR(VLOOKUP(MID(H16,1,2),PIRA!$B$1:$E$1144,2,FALSE),"")&" "&IFERROR(VLOOKUP(MID(I16,1,2),PIRA!$B$1:$E$1144,2,FALSE),"") -> Entropy and the Second Law | F16: =IFERROR(VLOOKUP(MID(G16,1,4),PIRA!$B$1:$E$1144,2,FALSE),"")&" "&IFERROR(VLOOKUP(MID(H16,1,4),PIRA!$B$1:$E$1144,2,FALSE),"")&" "&IFERROR(VLOOKUP(MID(I16,1,4),PIRA!$B$1:$E$1144,2,FALSE),"") -> Heat Cycles | G16: 4F30.01 | H16: =IFERROR(IF(VLOOKUP(G16,Demos!$B$3:$K$1368,2,FALSE)=0,"",VLOOKUP(G16,Demos!$B$3:$K$1368,2,FALSE)),"") | I16: =IFERROR(IF(VLOOKUP(G16,Demos!$B$3:$K$1368,3,FALSE)=0,"",VLOOKUP(G16,Demos!$B$3:$K$1368,3,FALSE)),"") | J16: =IFERROR(IF(VLOOKUP(G16,Demos!$B$3:$K$1368,4,FALSE)=0,"",VLOOKUP(G16,Demos!$B$3:$K$1368,4,FALSE)),"") | K16: Henk Schut | L16: Chris Klein | M16: 45444 | N16: =IFERROR(VLOOKUP(G16,Demos!$B$3:$K$1368,5,FALSE),"") -> Stirling Engine | O16: =IF(N16="","",COUNTIF($N$6:N2135, N16)) -> 18 | P16: =IFERROR(IF(VLOOKUP(G16,Demos!$B$3:$K$1368,6,FALSE)=0,"",VLOOKUP(G16,Demos!$B$3:$K$1368,6,FALSE)),"") -> http://www.de-monstrare.nl/pdf/Stirling%20engine.pdf | Q16: =IFERROR(IF(VLOOKUP(G16,Demos!$B$3:$K$1368,8,FALSE)=0,"",VLOOKUP(G16,Demos!$B$3:$K$1368,8,FALSE)),"") | R16: =IFERROR(IF(VLOOKUP(G16,Demos!$B$3:$K$1368,7,FALSE)=0,"",VLOOKUP(G16,Demos!$B$3:$K$1368,7,FALSE)),"") -> See from 01:02:03: U:\Elearning TP\Natk4all\college ted\dag 7 | U16: =IFERROR(VLOOKUP(G16,Demos!$B$7:N5910,12,FALSE),"")
A17: =ROW()-5 -> 12 | B17: TN2785 | C17: =IFERROR(VLOOKUP(B17, Courses!$C$3:$E$836, 2, FALSE),"") -> Physical Transport Phenomena | D17: =IFERROR(VLOOKUP(MID(G17,1,1), PIRA!$B$1:$E$1146, 2, FALSE),"") -> 4 Thermodynamics | E17: =IFERROR(VLOOKUP(MID(G17,1,2),PIRA!$B$1:$E$1144,2,FALSE),"")&" "&IFERROR(VLOOKUP(MID(H17,1,2),PIRA!$B$1:$E$1144,2,FALSE),"")&" "&IFERROR(VLOOKUP(MID(I17,1,2),PIRA!$B$1:$E$1144,2,FALSE),"") -> Heat and the First Law | F17: =IFERROR(VLOOKUP(MID(G17,1,4),PIRA!$B$1:$E$1144,2,FALSE),"")&" "&IFERROR(VLOOKUP(MID(H17,1,4),PIRA!$B$1:$E$1144,2,FALSE),"")&" "&IFERROR(VLOOKUP(MID(I17,1,4),PIRA!$B$1:$E$1144,2,FALSE),"") -> Convection | G17: 4B20.10 | H17: =IFERROR(IF(VLOOKUP(G17,Demos!$B$3:$K$1368,2,FALSE)=0,"",VLOOKUP(G17,Demos!$B$3:$K$1368,2,FALSE)),"") | I17: =IFERROR(IF(VLOOKUP(G17,Demos!$B$3:$K$1368,3,FALSE)=0,"",VLOOKUP(G17,Demos!$B$3:$K$1368,3,FALSE)),"") | J17: =IFERROR(IF(VLOOKUP(G17,Demos!$B$3:$K$1368,4,FALSE)=0,"",VLOOKUP(G17,Demos!$B$3:$K$1368,4,FALSE)),"") | K17: Martin Rohde | L17: Chris Klein | M17: 45443 | N17: =IFERROR(VLOOKUP(G17,Demos!$B$3:$K$1368,5,FALSE),"") -> Convection in a water container, heated from its bottom | O17: =IF(N17="","",COUNTIF($N$6:N2136, N17)) -> 9 | P17: =IFERROR(IF(VLOOKUP(G17,Demos!$B$3:$K$1368,6,FALSE)=0,"",VLOOKUP(G17,Demos!$B$3:$K$1368,6,FALSE)),"") -> N/A | Q17: =IFERROR(IF(VLOOKUP(G17,Demos!$B$3:$K$1368,8,FALSE)=0,"",VLOOKUP(G17,Demos!$B$3:$K$1368,8,FALSE)),"") | R17: =IFERROR(IF(VLOOKUP(G17,Demos!$B$3:$K$1368,7,FALSE)=0,"",VLOOKUP(G17,Demos!$B$3:$K$1368,7,FALSE)),"") -> See 2021 Zoomopname "opname hoorcollege 11.mp4" and Collegerama recording 2011/2012 - https://collegerama.tudelft.nl/ and 31 May 2023 "TN2786_012" recording from 00:06:20 and the calculation from 01:39:00 https://collegeramavideoportal.tudelft.nl/catalogue/tn2786/presentation/b21af4fd845e4bc3a51eff1850205d251d?academicYear=2022-2023-tn2786 | U17: =IFERROR(VLOOKUP(G17,Demos!$B$7:N5916,12,FALSE),"") -> 0
A18: =ROW()-5 -> 13 | B18: TN1201 | C18: =IFERROR(VLOOKUP(B18, Courses!$C$3:$E$836, 2, FALSE),"") -> Thermodynamics | D18: =IFERROR(VLOOKUP(MID(G18,1,1), PIRA!$B$1:$E$1146, 2, FALSE),"") -> 4 Thermodynamics | E18: =IFERROR(VLOOKUP(MID(G18,1,2),PIRA!$B$1:$E$1144,2,FALSE),"")&" "&IFERROR(VLOOKUP(MID(H18,1,2),PIRA!$B$1:$E$1144,2,FALSE),"")&" "&IFERROR(VLOOKUP(MID(I18,1,2),PIRA!$B$1:$E$1144,2,FALSE),"") -> Heat and the First Law | F18: =IFERROR(VLOOKUP(MID(G18,1,4),PIRA!$B$1:$E$1144,2,FALSE),"")&" "&IFERROR(VLOOKUP(MID(H18,1,4),PIRA!$B$1:$E$1144,2,FALSE),"")&" "&IFERROR(VLOOKUP(MID(I18,1,4),PIRA!$B$1:$E$1144,2,FALSE),"") -> Mechanical Equivalent of Heat | G18: 4B60.11 | H18: =IFERROR(IF(VLOOKUP(G18,Demos!$B$3:$K$1368,2,FALSE)=0,"",VLOOKUP(G18,Demos!$B$3:$K$1368,2,FALSE)),"") | I18: =IFERROR(IF(VLOOKUP(G18,Demos!$B$3:$K$1368,3,FALSE)=0,"",VLOOKUP(G18,Demos!$B$3:$K$1368,3,FALSE)),"") | J18: =IFERROR(IF(VLOOKUP(G18,Demos!$B$3:$K$1368,4,FALSE)=0,"",VLOOKUP(G18,Demos!$B$3:$K$1368,4,FALSE)),"") | K18: Henk Schut | L18: Chris Klein | M18: 45443 | N18: =IFERROR(VLOOKUP(G18,Demos!$B$3:$K$1368,5,FALSE),"") -> Dropping Lead Shot | O18: =IF(N18="","",COUNTIF($N$6:N2137, N18)) -> 10 | P18: =IFERROR(IF(VLOOKUP(G18,Demos!$B$3:$K$1368,6,FALSE)=0,"",VLOOKUP(G18,Demos!$B$3:$K$1368,6,FALSE)),"") -> N/A | Q18: =IFERROR(IF(VLOOKUP(G18,Demos!$B$3:$K$1368,8,FALSE)=0,"",VLOOKUP(G18,Demos!$B$3:$K$1368,8,FALSE)),"") | R18: =IFERROR(IF(VLOOKUP(G18,Demos!$B$3:$K$1368,7,FALSE)=0,"",VLOOKUP(G18,Demos!$B$3:$K$1368,7,FALSE)),"") | U18: =IFERROR(VLOOKUP(G18,Demos!$B$7:N5911,12,FALSE),"")
A19: =ROW()-5 -> 14 | B19: TN1201 | C19: =IFERROR(VLOOKUP(B19, Courses!$C$3:$E$836, 2, FALSE),"") -> Thermodynamics | D19: =IFERROR(VLOOKUP(MID(G19,1,1), PIRA!$B$1:$E$1146, 2, FALSE),"") -> 4 Thermodynamics | E19: =IFERROR(VLOOKUP(MID(G19,1,2),PIRA!$B$1:$E$1144,2,FALSE),"")&" "&IFERROR(VLOOKUP(MID(H19,1,2),PIRA!$B$1:$E$1144,2,FALSE),"")&" "&IFERROR(VLOOKUP(MID(I19,1,2),PIRA!$B$1:$E$1144,2,FALSE),"") -> Thermal Properties of Matter | F19: =IFERROR(VLOOKUP(MID(G19,1,4),PIRA!$B$1:$E$1144,2,FALSE),"")&" "&IFERROR(VLOOKUP(MID(H19,1,4),PIRA!$B$1:$E$1144,2,FALSE),"")&" "&IFERROR(VLOOKUP(MID(I19,1,4),PIRA!$B$1:$E$1144,2,FALSE),"") -> Thermometry | G19: 4A10.02 | H19: =IFERROR(IF(VLOOKUP(G19,Demos!$B$3:$K$1368,2,FALSE)=0,"",VLOOKUP(G19,Demos!$B$3:$K$1368,2,FALSE)),"") | I19: =IFERROR(IF(VLOOKUP(G19,Demos!$B$3:$K$1368,3,FALSE)=0,"",VLOOKUP(G19,Demos!$B$3:$K$1368,3,FALSE)),"") | J19: =IFERROR(IF(VLOOKUP(G19,Demos!$B$3:$K$1368,4,FALSE)=0,"",VLOOKUP(G19,Demos!$B$3:$K$1368,4,FALSE)),"") | K19: Henk Schut | L19: Chris Klein | M19: 45442 | N19: =IFERROR(VLOOKUP(G19,Demos!$B$3:$K$1368,5,FALSE),"") -> Inverted Thermometer | O19: =IF(N19="","",COUNTIF($N$6:N2138, N19)) -> 10 | P19: =IFERROR(IF(VLOOKUP(G19,Demos!$B$3:$K$1368,6,FALSE)=0,"",VLOOKUP(G19,Demos!$B$3:$K$1368,6,FALSE)),"") -> http://www.de-monstrare.nl/pdf/Inverted%20thermometer.pdf | Q19: =IFERROR(IF(VLOOKUP(G19,Demos!$B$3:$K$1368,8,FALSE)=0,"",VLOOKUP(G19,Demos!$B$3:$K$1368,8,FALSE)),"") | R19: =IFERROR(IF(VLOOKUP(G19,Demos!$B$3:$K$1368,7,FALSE)=0,"",VLOOKUP(G19,Demos!$B$3:$K$1368,7,FALSE)),"") | U19: =IFERROR(VLOOKUP(G19,Demos!$B$7:N5915,12,FALSE),"")
A20: =ROW()-5 -> 15 | B20: TN2054 | C20: =IFERROR(VLOOKUP(B20, Courses!$C$3:$E$836, 2, FALSE),"") -> Electromagnetism | D20: =IFERROR(VLOOKUP(MID(G20,1,1), PIRA!$B$1:$E$1146, 2, FALSE),"") -> 5 Electricity and Magnetism | E20: =IFERROR(VLOOKUP(MID(G20,1,2),PIRA!$B$1:$E$1144,2,FALSE),"")&" "&IFERROR(VLOOKUP(MID(H20,1,2),PIRA!$B$1:$E$1144,2,FALSE),"")&" "&IFERROR(VLOOKUP(MID(I20,1,2),PIRA!$B$1:$E$1144,2,FALSE),"") -> Magnetic Fields and Forces | F20: =IFERROR(VLOOKUP(MID(G20,1,4),PIRA!$B$1:$E$1144,2,FALSE),"")&" "&IFERROR(VLOOKUP(MID(H20,1,4),PIRA!$B$1:$E$1144,2,FALSE),"")&" "&IFERROR(VLOOKUP(MID(I20,1,4),PIRA!$B$1:$E$1144,2,FALSE),"") -> Force on Current in Wires | G20: 5H40.10 | H20: =IFERROR(IF(VLOOKUP(G20,Demos!$B$3:$K$1368,2,FALSE)=0,"",VLOOKUP(G20,Demos!$B$3:$K$1368,2,FALSE)),"") | I20: =IFERROR(IF(VLOOKUP(G20,Demos!$B$3:$K$1368,3,FALSE)=0,"",VLOOKUP(G20,Demos!$B$3:$K$1368,3,FALSE)),"") | J20: =IFERROR(IF(VLOOKUP(G20,Demos!$B$3:$K$1368,4,FALSE)=0,"",VLOOKUP(G20,Demos!$B$3:$K$1368,4,FALSE)),"") | K20: Jeroen Kalkman | L20: Martin Verweij | M20: 45442 | N20: =IFERROR(VLOOKUP(G20,Demos!$B$3:$K$1368,5,FALSE),"") -> Parallel Wires | O20: =IF(N20="","",COUNTIF($N$6:N2139, N20)) -> 12 | P20: =IFERROR(IF(VLOOKUP(G20,Demos!$B$3:$K$1368,6,FALSE)=0,"",VLOOKUP(G20,Demos!$B$3:$K$1368,6,FALSE)),"") -> www.de-monstrare.nl/pdf/parallel%20wires.pdf | Q20: =IFERROR(IF(VLOOKUP(G20,Demos!$B$3:$K$1368,8,FALSE)=0,"",VLOOKUP(G20,Demos!$B$3:$K$1368,8,FALSE)),"") | R20: =IFERROR(IF(VLOOKUP(G20,Demos!$B$3:$K$1368,7,FALSE)=0,"",VLOOKUP(G20,Demos!$B$3:$K$1368,7,FALSE)),"") | U20: =IFERROR(VLOOKUP(G20,Demos!$B$7:N5881,12,FALSE),"")
A21: =ROW()-5 -> 16 | B21: TN1201 | C21: =IFERROR(VLOOKUP(B21, Courses!$C$3:$E$836, 2, FALSE),"") -> Thermodynamics | D21: =IFERROR(VLOOKUP(MID(G21,1,1), PIRA!$B$1:$E$1146, 2, FALSE),"") -> 4 Thermodynamics | E21: =IFERROR(VLOOKUP(MID(G21,1,2),PIRA!$B$1:$E$1144,2,FALSE),"")&" "&IFERROR(VLOOKUP(MID(H21,1,2),PIRA!$B$1:$E$1144,2,FALSE),"")&" "&IFERROR(VLOOKUP(MID(I21,1,2),PIRA!$B$1:$E$1144,2,FALSE),"") -> Change of State | F21: =IFERROR(VLOOKUP(MID(G21,1,4),PIRA!$B$1:$E$1144,2,FALSE),"")&" "&IFERROR(VLOOKUP(MID(H21,1,4),PIRA!$B$1:$E$1144,2,FALSE),"")&" "&IFERROR(VLOOKUP(MID(I21,1,4),PIRA!$B$1:$E$1144,2,FALSE),"") -> PVT Surfaces | G21: 4C10.02 | H21: =IFERROR(IF(VLOOKUP(G21,Demos!$B$3:$K$1368,2,FALSE)=0,"",VLOOKUP(G21,Demos!$B$3:$K$1368,2,FALSE)),"") | I21: =IFERROR(IF(VLOOKUP(G21,Demos!$B$3:$K$1368,3,FALSE)=0,"",VLOOKUP(G21,Demos!$B$3:$K$1368,3,FALSE)),"") | J21: =IFERROR(IF(VLOOKUP(G21,Demos!$B$3:$K$1368,4,FALSE)=0,"",VLOOKUP(G21,Demos!$B$3:$K$1368,4,FALSE)),"") | K21: Henk Schut | L21: Chris Klein | M21: 45437 | N21: =IFERROR(VLOOKUP(G21,Demos!$B$3:$K$1368,5,FALSE),"") -> Work = int(PdV) | O21: =IF(N21="","",COUNTIF($N$6:N2140, N21)) -> 11 | P21: =IFERROR(IF(VLOOKUP(G21,Demos!$B$3:$K$1368,6,FALSE)=0,"",VLOOKUP(G21,Demos!$B$3:$K$1368,6,FALSE)),"") -> http://www.de-monstrare.nl/pdf/pdV.pdf | Q21: =IFERROR(IF(VLOOKUP(G21,Demos!$B$3:$K$1368,8,FALSE)=0,"",VLOOKUP(G21,Demos!$B$3:$K$1368,8,FALSE)),"") | R21: =IFERROR(IF(VLOOKUP(G21,Demos!$B$3:$K$1368,7,FALSE)=0,"",VLOOKUP(G21,Demos!$B$3:$K$1368,7,FALSE)),"") | T21: No (lecturer decided not to use demo) | U21: =IFERROR(VLOOKUP(G21,Demos!$B$7:N5912,12,FALSE),"")
A22: =ROW()-5 -> 17 | B22: TN1201 | C22: =IFERROR(VLOOKUP(B22, Courses!$C$3:$E$836, 2, FALSE),"") -> Thermodynamics | D22: =IFERROR(VLOOKUP(MID(G22,1,1), PIRA!$B$1:$E$1146, 2, FALSE),"") -> 4 Thermodynamics | E22: =IFERROR(VLOOKUP(MID(G22,1,2),PIRA!$B$1:$E$1144,2,FALSE),"")&" "&IFERROR(VLOOKUP(MID(H22,1,2),PIRA!$B$1:$E$1144,2,FALSE),"")&" "&IFERROR(VLOOKUP(MID(I22,1,2),PIRA!$B$1:$E$1144,2,FALSE),"") -> Change of State | F22: =IFERROR(VLOOKUP(MID(G22,1,4),PIRA!$B$1:$E$1144,2,FALSE),"")&" "&IFERROR(VLOOKUP(MID(H22,1,4),PIRA!$B$1:$E$1144,2,FALSE),"")&" "&IFERROR(VLOOKUP(MID(I22,1,4),PIRA!$B$1:$E$1144,2,FALSE),"") -> Vapor Pressure | G22: 4C33.02 | H22: =IFERROR(IF(VLOOKUP(G22,Demos!$B$3:$K$1368,2,FALSE)=0,"",VLOOKUP(G22,Demos!$B$3:$K$1368,2,FALSE)),"") | I22: =IFERROR(IF(VLOOKUP(G22,Demos!$B$3:$K$1368,3,FALSE)=0,"",VLOOKUP(G22,Demos!$B$3:$K$1368,3,FALSE)),"") | J22: =IFERROR(IF(VLOOKUP(G22,Demos!$B$3:$K$1368,4,FALSE)=0,"",VLOOKUP(G22,Demos!$B$3:$K$1368,4,FALSE)),"") | K22: Henk Schut | L22: Chris Klein | M22: 45436 | N22: =IFERROR(VLOOKUP(G22,Demos!$B$3:$K$1368,5,FALSE),"") -> Boiling Water at Reduced Pressure | O22: =IF(N22="","",COUNTIF($N$6:N2141, N22)) -> 10 | P22: =IFERROR(IF(VLOOKUP(G22,Demos!$B$3:$K$1368,6,FALSE)=0,"",VLOOKUP(G22,Demos!$B$3:$K$1368,6,FALSE)),"") -> http://www.de-monstrare.nl/pdf/Boiling%20water%20at%20reduced%20pressure.pdf | Q22: =IFERROR(IF(VLOOKUP(G22,Demos!$B$3:$K$1368,8,FALSE)=0,"",VLOOKUP(G22,Demos!$B$3:$K$1368,8,FALSE)),"") | R22: =IFERROR(IF(VLOOKUP(G22,Demos!$B$3:$K$1368,7,FALSE)=0,"",VLOOKUP(G22,Demos!$B$3:$K$1368,7,FALSE)),"") | T22: No (lecturer decided not to use demo) | U22: =IFERROR(VLOOKUP(G22,Demos!$B$7:N5914,12,FALSE),"")
A23: =ROW()-5 -> 18 | B23: TN1201 | C23: =IFERROR(VLOOKUP(B23, Courses!$C$3:$E$836, 2, FALSE),"") -> Thermodynamics | D23: =IFERROR(VLOOKUP(MID(G23,1,1), PIRA!$B$1:$E$1146, 2, FALSE),"") -> 4 Thermodynamics | E23: =IFERROR(VLOOKUP(MID(G23,1,2),PIRA!$B$1:$E$1144,2,FALSE),"")&" "&IFERROR(VLOOKUP(MID(H23,1,2),PIRA!$B$1:$E$1144,2,FALSE),"")&" "&IFERROR(VLOOKUP(MID(I23,1,2),PIRA!$B$1:$E$1144,2,FALSE),"") -> Change of State | F23: =IFERROR(VLOOKUP(MID(G23,1,4),PIRA!$B$1:$E$1144,2,FALSE),"")&" "&IFERROR(VLOOKUP(MID(H23,1,4),PIRA!$B$1:$E$1144,2,FALSE),"")&" "&IFERROR(VLOOKUP(MID(I23,1,4),PIRA!$B$1:$E$1144,2,FALSE),"") -> Critical Point | G23: 4C50.20 | H23: =IFERROR(IF(VLOOKUP(G23,Demos!$B$3:$K$1368,2,FALSE)=0,"",VLOOKUP(G23,Demos!$B$3:$K$1368,2,FALSE)),"") | I23: =IFERROR(IF(VLOOKUP(G23,Demos!$B$3:$K$1368,3,FALSE)=0,"",VLOOKUP(G23,Demos!$B$3:$K$1368,3,FALSE)),"") | J23: =IFERROR(IF(VLOOKUP(G23,Demos!$B$3:$K$1368,4,FALSE)=0,"",VLOOKUP(G23,Demos!$B$3:$K$1368,4,FALSE)),"") | K23: Henk Schut | L23: Chris Klein | M23: 45436 | N23: =IFERROR(VLOOKUP(G23,Demos!$B$3:$K$1368,5,FALSE),"") -> Critical Opalscence | O23: =IF(N23="","",COUNTIF($N$6:N2142, N23)) -> 10 | P23: =IFERROR(IF(VLOOKUP(G23,Demos!$B$3:$K$1368,6,FALSE)=0,"",VLOOKUP(G23,Demos!$B$3:$K$1368,6,FALSE)),"") -> N/A | Q23: =IFERROR(IF(VLOOKUP(G23,Demos!$B$3:$K$1368,8,FALSE)=0,"",VLOOKUP(G23,Demos!$B$3:$K$1368,8,FALSE)),"") | R23: =IFERROR(IF(VLOOKUP(G23,Demos!$B$3:$K$1368,7,FALSE)=0,"",VLOOKUP(G23,Demos!$B$3:$K$1368,7,FALSE)),"") | T23: No (lecturer decided not to use demo) | U23: =IFERROR(VLOOKUP(G23,Demos!$B$7:N5913,12,FALSE),"")
A24: =ROW()-5 -> 19 | B24: WB2330 | C24: =IFERROR(VLOOKUP(B24, Courses!$C$3:$E$836, 2, FALSE),"") -> Materiaalkunde | D24: =IFERROR(VLOOKUP(MID(G24,1,1), PIRA!$B$1:$E$1146, 2, FALSE),"") -> 5 Electricity and Magnetism | E24: =IFERROR(VLOOKUP(MID(G24,1,2),PIRA!$B$1:$E$1144,2,FALSE),"")&" "&IFERROR(VLOOKUP(MID(H24,1,2),PIRA!$B$1:$E$1144,2,FALSE),"")&" "&IFERROR(VLOOKUP(MID(I24,1,2),PIRA!$B$1:$E$1144,2,FALSE),"") -> Magnetic Materials | F24: =IFERROR(VLOOKUP(MID(G24,1,4),PIRA!$B$1:$E$1144,2,FALSE),"")&" "&IFERROR(VLOOKUP(MID(H24,1,4),PIRA!$B$1:$E$1144,2,FALSE),"")&" "&IFERROR(VLOOKUP(MID(I24,1,4),PIRA!$B$1:$E$1144,2,FALSE),"") -> Temperature and Magnetism | G24: 5G50.50 | H24: =IFERROR(IF(VLOOKUP(G24,Demos!$B$3:$K$1368,2,FALSE)=0,"",VLOOKUP(G24,Demos!$B$3:$K$1368,2,FALSE)),"") | I24: =IFERROR(IF(VLOOKUP(G24,Demos!$B$3:$K$1368,3,FALSE)=0,"",VLOOKUP(G24,Demos!$B$3:$K$1368,3,FALSE)),"") | J24: =IFERROR(IF(VLOOKUP(G24,Demos!$B$3:$K$1368,4,FALSE)=0,"",VLOOKUP(G24,Demos!$B$3:$K$1368,4,FALSE)),"") | K24: Ron Haaksman | L24: Erik Offerman | M24: 45430 | N24: =IFERROR(VLOOKUP(G24,Demos!$B$3:$K$1368,5,FALSE),"") -> Levitation (superconductivity, flux pinning) | O24: =IF(N24="","",COUNTIF($N$6:N2143, N24)) -> 17 | P24: =IFERROR(IF(VLOOKUP(G24,Demos!$B$3:$K$1368,6,FALSE)=0,"",VLOOKUP(G24,Demos!$B$3:$K$1368,6,FALSE)),"") -> N/A | Q24: =IFERROR(IF(VLOOKUP(G24,Demos!$B$3:$K$1368,8,FALSE)=0,"",VLOOKUP(G24,Demos!$B$3:$K$1368,8,FALSE)),"") | R24: =IFERROR(IF(VLOOKUP(G24,Demos!$B$3:$K$1368,7,FALSE)=0,"",VLOOKUP(G24,Demos!$B$3:$K$1368,7,FALSE)),"") -> See: https://www.youtube.com/watch?v=H3GuLepOKFY&list=PLYMFB4TVFdJJ4DsfXdY6yzDCDgLLiC4ya&index=5 | T24: No (lecturer decided not to use demo) | U24: =IFERROR(VLOOKUP(G24,Demos!$B$7:N5917,12,FALSE),"")
A25: =ROW()-5 -> 20 | B25: TN2785 | C25: =IFERROR(VLOOKUP(B25, Courses!$C$3:$E$836, 2, FALSE),"") -> Physical Transport Phenomena | D25: =IFERROR(VLOOKUP(MID(G25,1,1), PIRA!$B$1:$E$1146, 2, FALSE),"") -> 4 Thermodynamics | E25: =IFERROR(VLOOKUP(MID(G25,1,2),PIRA!$B$1:$E$1144,2,FALSE),"")&" "&IFERROR(VLOOKUP(MID(H25,1,2),PIRA!$B$1:$E$1144,2,FALSE),"")&" "&IFERROR(VLOOKUP(MID(I25,1,2),PIRA!$B$1:$E$1144,2,FALSE),"") -> Heat and the First Law | F25: =IFERROR(VLOOKUP(MID(G25,1,4),PIRA!$B$1:$E$1144,2,FALSE),"")&" "&IFERROR(VLOOKUP(MID(H25,1,4),PIRA!$B$1:$E$1144,2,FALSE),"")&" "&IFERROR(VLOOKUP(MID(I25,1,4),PIRA!$B$1:$E$1144,2,FALSE),"") -> Conduction | G25: 4B30.21 | H25: =IFERROR(IF(VLOOKUP(G25,Demos!$B$3:$K$1368,2,FALSE)=0,"",VLOOKUP(G25,Demos!$B$3:$K$1368,2,FALSE)),"") | I25: =IFERROR(IF(VLOOKUP(G25,Demos!$B$3:$K$1368,3,FALSE)=0,"",VLOOKUP(G25,Demos!$B$3:$K$1368,3,FALSE)),"") | J25: =IFERROR(IF(VLOOKUP(G25,Demos!$B$3:$K$1368,4,FALSE)=0,"",VLOOKUP(G25,Demos!$B$3:$K$1368,4,FALSE)),"") | K25: Chris Klein | L25: Martin Rohde | M25: 45424 | N25: =IFERROR(VLOOKUP(G25,Demos!$B$3:$K$1368,5,FALSE),"") -> Conduction Slab | O25: =IF(N25="","",COUNTIF($N$6:N2144, N25)) -> 7 | P25: =IFERROR(IF(VLOOKUP(G25,Demos!$B$3:$K$1368,6,FALSE)=0,"",VLOOKUP(G25,Demos!$B$3:$K$1368,6,FALSE)),"") -> N/A | Q25: =IFERROR(IF(VLOOKUP(G25,Demos!$B$3:$K$1368,8,FALSE)=0,"",VLOOKUP(G25,Demos!$B$3:$K$1368,8,FALSE)),"") -> A stainless steel slab, heat from one end. Heat sensitive film is stuck on the plate, such that the heat conduction can be observed. | R25: =IFERROR(IF(VLOOKUP(G25,Demos!$B$3:$K$1368,7,FALSE)=0,"",VLOOKUP(G25,Demos!$B$3:$K$1368,7,FALSE)),"") -> See 2021 Zoomopname "opname hoorcollege 7.mp4" and Collegerama recording 2011/2012 - https://collegerama.tudelft.nl/Mediasite/Channel/as-bsc-tn/watch/b6b2331bc2144aba9c70d01fb3cfa6311d and 12 May 2023 "TN2786_008" recording from 00:04:00 on https://collegeramavideoportal.tudelft.nl/catalogue/tn2786/presentation/1701937ea67942759c7f810749f0fb891d?academicYear=2022-2023-tn2786 | U25: =IFERROR(VLOOKUP(G25,Demos!$B$7:N5918,12,FALSE),"") -> 0
A26: =ROW()-5 -> 21 | B26: TN2054 | C26: =IFERROR(VLOOKUP(B26, Courses!$C$3:$E$836, 2, FALSE),"") -> Electromagnetism | D26: =IFERROR(VLOOKUP(MID(G26,1,1), PIRA!$B$1:$E$1146, 2, FALSE),"") -> 5 Electricity and Magnetism | E26: =IFERROR(VLOOKUP(MID(G26,1,2),PIRA!$B$1:$E$1144,2,FALSE),"")&" "&IFERROR(VLOOKUP(MID(H26,1,2),PIRA!$B$1:$E$1144,2,FALSE),"")&" "&IFERROR(VLOOKUP(MID(I26,1,2),PIRA!$B$1:$E$1144,2,FALSE),"") -> Capacitance | F26: =IFERROR(VLOOKUP(MID(G26,1,4),PIRA!$B$1:$E$1144,2,FALSE),"")&" "&IFERROR(VLOOKUP(MID(H26,1,4),PIRA!$B$1:$E$1144,2,FALSE),"")&" "&IFERROR(VLOOKUP(MID(I26,1,4),PIRA!$B$1:$E$1144,2,FALSE),"") -> Capacitors | G26: 5C10.20 | H26: =IFERROR(IF(VLOOKUP(G26,Demos!$B$3:$K$1368,2,FALSE)=0,"",VLOOKUP(G26,Demos!$B$3:$K$1368,2,FALSE)),"") | I26: =IFERROR(IF(VLOOKUP(G26,Demos!$B$3:$K$1368,3,FALSE)=0,"",VLOOKUP(G26,Demos!$B$3:$K$1368,3,FALSE)),"") | J26: =IFERROR(IF(VLOOKUP(G26,Demos!$B$3:$K$1368,4,FALSE)=0,"",VLOOKUP(G26,Demos!$B$3:$K$1368,4,FALSE)),"") | K26: Niels van Dijk | L26: Martin Verweij | M26: 45414 | N26: =IFERROR(VLOOKUP(G26,Demos!$B$3:$K$1368,5,FALSE),"") -> Capacitor (1) Spacing between the Plates | O26: =IF(N26="","",COUNTIF($N$6:N2145, N26)) -> 15 | P26: =IFERROR(IF(VLOOKUP(G26,Demos!$B$3:$K$1368,6,FALSE)=0,"",VLOOKUP(G26,Demos!$B$3:$K$1368,6,FALSE)),"") -> www.de-monstrare.nl/.../Capacitor%20_1_ %20Spacing%20between%20the%20plates.pdf | Q26: =IFERROR(IF(VLOOKUP(G26,Demos!$B$3:$K$1368,8,FALSE)=0,"",VLOOKUP(G26,Demos!$B$3:$K$1368,8,FALSE)),"") | R26: =IFERROR(IF(VLOOKUP(G26,Demos!$B$3:$K$1368,7,FALSE)=0,"",VLOOKUP(G26,Demos!$B$3:$K$1368,7,FALSE)),"") | U26: =IFERROR(VLOOKUP(G26,Demos!$B$7:N5927,12,FALSE),"")
A27: =ROW()-5 -> 22 | B27: TN2785 | C27: =IFERROR(VLOOKUP(B27, Courses!$C$3:$E$836, 2, FALSE),"") -> Physical Transport Phenomena | D27: =IFERROR(VLOOKUP(MID(G27,1,1), PIRA!$B$1:$E$1146, 2, FALSE),"") | E27: =IFERROR(VLOOKUP(MID(G27,1,2),PIRA!$B$1:$E$1144,2,FALSE),"")&" "&IFERROR(VLOOKUP(MID(H27,1,2),PIRA!$B$1:$E$1144,2,FALSE),"")&" "&IFERROR(VLOOKUP(MID(I27,1,2),PIRA!$B$1:$E$1144,2,FALSE),"") | F27: =IFERROR(VLOOKUP(MID(G27,1,4),PIRA!$B$1:$E$1144,2,FALSE),"")&" "&IFERROR(VLOOKUP(MID(H27,1,4),PIRA!$B$1:$E$1144,2,FALSE),"")&" "&IFERROR(VLOOKUP(MID(I27,1,4),PIRA!$B$1:$E$1144,2,FALSE),"") | H27: =IFERROR(IF(VLOOKUP(G27,Demos!$B$3:$K$1368,2,FALSE)=0,"",VLOOKUP(G27,Demos!$B$3:$K$1368,2,FALSE)),"") | I27: =IFERROR(IF(VLOOKUP(G27,Demos!$B$3:$K$1368,3,FALSE)=0,"",VLOOKUP(G27,Demos!$B$3:$K$1368,3,FALSE)),"") | J27: =IFERROR(IF(VLOOKUP(G27,Demos!$B$3:$K$1368,4,FALSE)=0,"",VLOOKUP(G27,Demos!$B$3:$K$1368,4,FALSE)),"") | K27: Chris Klein | L27: Martin Rohde | M27: 45410 | N27: =IFERROR(VLOOKUP(G27,Demos!$B$3:$K$1368,5,FALSE),"") | O27: =IF(N27="","",COUNTIF($N$6:N2146, N27)) | P27: =IFERROR(IF(VLOOKUP(G27,Demos!$B$3:$K$1368,6,FALSE)=0,"",VLOOKUP(G27,Demos!$B$3:$K$1368,6,FALSE)),"") | Q27: =IFERROR(IF(VLOOKUP(G27,Demos!$B$3:$K$1368,8,FALSE)=0,"",VLOOKUP(G27,Demos!$B$3:$K$1368,8,FALSE)),"") | R27: =IFERROR(IF(VLOOKUP(G27,Demos!$B$3:$K$1368,7,FALSE)=0,"",VLOOKUP(G27,Demos!$B$3:$K$1368,7,FALSE)),"") | T27: No (lecturer decided not to use demo) | U27: =IFERROR(VLOOKUP(G27,Demos!$B$7:N5919,12,FALSE),"")
A28: =ROW()-5 -> 23 | B28: TN2785 | C28: =IFERROR(VLOOKUP(B28, Courses!$C$3:$E$836, 2, FALSE),"") -> Physical Transport Phenomena | D28: =IFERROR(VLOOKUP(MID(G28,1,1), PIRA!$B$1:$E$1146, 2, FALSE),"") | E28: =IFERROR(VLOOKUP(MID(G28,1,2),PIRA!$B$1:$E$1144,2,FALSE),"")&" "&IFERROR(VLOOKUP(MID(H28,1,2),PIRA!$B$1:$E$1144,2,FALSE),"")&" "&IFERROR(VLOOKUP(MID(I28,1,2),PIRA!$B$1:$E$1144,2,FALSE),"") | F28: =IFERROR(VLOOKUP(MID(G28,1,4),PIRA!$B$1:$E$1144,2,FALSE),"")&" "&IFERROR(VLOOKUP(MID(H28,1,4),PIRA!$B$1:$E$1144,2,FALSE),"")&" "&IFERROR(VLOOKUP(MID(I28,1,4),PIRA!$B$1:$E$1144,2,FALSE),"") | H28: =IFERROR(IF(VLOOKUP(G28,Demos!$B$3:$K$1368,2,FALSE)=0,"",VLOOKUP(G28,Demos!$B$3:$K$1368,2,FALSE)),"") | I28: =IFERROR(IF(VLOOKUP(G28,Demos!$B$3:$K$1368,3,FALSE)=0,"",VLOOKUP(G28,Demos!$B$3:$K$1368,3,FALSE)),"") | J28: =IFERROR(IF(VLOOKUP(G28,Demos!$B$3:$K$1368,4,FALSE)=0,"",VLOOKUP(G28,Demos!$B$3:$K$1368,4,FALSE)),"") | K28: Martin Rohde | M28: 45410 | N28: =IFERROR(VLOOKUP(G28,Demos!$B$3:$K$1368,5,FALSE),"") | O28: =IF(N28="","",COUNTIF($N$6:N2147, N28)) | P28: =IFERROR(IF(VLOOKUP(G28,Demos!$B$3:$K$1368,6,FALSE)=0,"",VLOOKUP(G28,Demos!$B$3:$K$1368,6,FALSE)),"") | Q28: =IFERROR(IF(VLOOKUP(G28,Demos!$B$3:$K$1368,8,FALSE)=0,"",VLOOKUP(G28,Demos!$B$3:$K$1368,8,FALSE)),"") | R28: =IFERROR(IF(VLOOKUP(G28,Demos!$B$3:$K$1368,7,FALSE)=0,"",VLOOKUP(G28,Demos!$B$3:$K$1368,7,FALSE)),"") | T28: No (no setup done) | U28: =IFERROR(VLOOKUP(G28,Demos!$B$7:N5920,12,FALSE),"")
A29: =ROW()-5 -> 24 | B29: TN2785 | C29: =IFERROR(VLOOKUP(B29, Courses!$C$3:$E$836, 2, FALSE),"") -> Physical Transport Phenomena | D29: =IFERROR(VLOOKUP(MID(G29,1,1), PIRA!$B$1:$E$1146, 2, FALSE),"") | E29: =IFERROR(VLOOKUP(MID(G29,1,2),PIRA!$B$1:$E$1144,2,FALSE),"")&" "&IFERROR(VLOOKUP(MID(H29,1,2),PIRA!$B$1:$E$1144,2,FALSE),"")&" "&IFERROR(VLOOKUP(MID(I29,1,2),PIRA!$B$1:$E$1144,2,FALSE),"") | F29: =IFERROR(VLOOKUP(MID(G29,1,4),PIRA!$B$1:$E$1144,2,FALSE),"")&" "&IFERROR(VLOOKUP(MID(H29,1,4),PIRA!$B$1:$E$1144,2,FALSE),"")&" "&IFERROR(VLOOKUP(MID(I29,1,4),PIRA!$B$1:$E$1144,2,FALSE),"") | H29: =IFERROR(IF(VLOOKUP(G29,Demos!$B$3:$K$1368,2,FALSE)=0,"",VLOOKUP(G29,Demos!$B$3:$K$1368,2,FALSE)),"") | I29: =IFERROR(IF(VLOOKUP(G29,Demos!$B$3:$K$1368,3,FALSE)=0,"",VLOOKUP(G29,Demos!$B$3:$K$1368,3,FALSE)),"") | J29: =IFERROR(IF(VLOOKUP(G29,Demos!$B$3:$K$1368,4,FALSE)=0,"",VLOOKUP(G29,Demos!$B$3:$K$1368,4,FALSE)),"") | K29: Martin Rohde | M29: 45410 | N29: =IFERROR(VLOOKUP(G29,Demos!$B$3:$K$1368,5,FALSE),"") | O29: =IF(N29="","",COUNTIF($N$6:N2148, N29)) | P29: =IFERROR(IF(VLOOKUP(G29,Demos!$B$3:$K$1368,6,FALSE)=0,"",VLOOKUP(G29,Demos!$B$3:$K$1368,6,FALSE)),"") | Q29: =IFERROR(IF(VLOOKUP(G29,Demos!$B$3:$K$1368,8,FALSE)=0,"",VLOOKUP(G29,Demos!$B$3:$K$1368,8,FALSE)),"") | R29: =IFERROR(IF(VLOOKUP(G29,Demos!$B$3:$K$1368,7,FALSE)=0,"",VLOOKUP(G29,Demos!$B$3:$K$1368,7,FALSE)),"") | T29: No (no setup done) | U29: =IFERROR(VLOOKUP(G29,Demos!$B$7:N5921,12,FALSE),"")
A30: =ROW()-5 -> 25 | B30: TN2785 | C30: =IFERROR(VLOOKUP(B30, Courses!$C$3:$E$836, 2, FALSE),"") -> Physical Transport Phenomena | D30: =IFERROR(VLOOKUP(MID(G30,1,1), PIRA!$B$1:$E$1146, 2, FALSE),"") | E30: =IFERROR(VLOOKUP(MID(G30,1,2),PIRA!$B$1:$E$1144,2,FALSE),"")&" "&IFERROR(VLOOKUP(MID(H30,1,2),PIRA!$B$1:$E$1144,2,FALSE),"")&" "&IFERROR(VLOOKUP(MID(I30,1,2),PIRA!$B$1:$E$1144,2,FALSE),"") | F30: =IFERROR(VLOOKUP(MID(G30,1,4),PIRA!$B$1:$E$1144,2,FALSE),"")&" "&IFERROR(VLOOKUP(MID(H30,1,4),PIRA!$B$1:$E$1144,2,FALSE),"")&" "&IFERROR(VLOOKUP(MID(I30,1,4),PIRA!$B$1:$E$1144,2,FALSE),"") | H30: =IFERROR(IF(VLOOKUP(G30,Demos!$B$3:$K$1368,2,FALSE)=0,"",VLOOKUP(G30,Demos!$B$3:$K$1368,2,FALSE)),"") | I30: =IFERROR(IF(VLOOKUP(G30,Demos!$B$3:$K$1368,3,FALSE)=0,"",VLOOKUP(G30,Demos!$B$3:$K$1368,3,FALSE)),"") | J30: =IFERROR(IF(VLOOKUP(G30,Demos!$B$3:$K$1368,4,FALSE)=0,"",VLOOKUP(G30,Demos!$B$3:$K$1368,4,FALSE)),"") | K30: Martin Rohde | M30: 45410 | N30: =IFERROR(VLOOKUP(G30,Demos!$B$3:$K$1368,5,FALSE),"") | O30: =IF(N30="","",COUNTIF($N$6:N2149, N30)) | P30: =IFERROR(IF(VLOOKUP(G30,Demos!$B$3:$K$1368,6,FALSE)=0,"",VLOOKUP(G30,Demos!$B$3:$K$1368,6,FALSE)),"") | Q30: =IFERROR(IF(VLOOKUP(G30,Demos!$B$3:$K$1368,8,FALSE)=0,"",VLOOKUP(G30,Demos!$B$3:$K$1368,8,FALSE)),"") | R30: =IFERROR(IF(VLOOKUP(G30,Demos!$B$3:$K$1368,7,FALSE)=0,"",VLOOKUP(G30,Demos!$B$3:$K$1368,7,FALSE)),"") | T30: No (setup malfunctioning) | U30: =IFERROR(VLOOKUP(G30,Demos!$B$7:N5922,12,FALSE),"")
A31: =ROW()-5 -> 26 | B31: TN2785 | C31: =IFERROR(VLOOKUP(B31, Courses!$C$3:$E$836, 2, FALSE),"") -> Physical Transport Phenomena | D31: =IFERROR(VLOOKUP(MID(G31,1,1), PIRA!$B$1:$E$1146, 2, FALSE),"") | E31: =IFERROR(VLOOKUP(MID(G31,1,2),PIRA!$B$1:$E$1144,2,FALSE),"")&" "&IFERROR(VLOOKUP(MID(H31,1,2),PIRA!$B$1:$E$1144,2,FALSE),"")&" "&IFERROR(VLOOKUP(MID(I31,1,2),PIRA!$B$1:$E$1144,2,FALSE),"") | F31: =IFERROR(VLOOKUP(MID(G31,1,4),PIRA!$B$1:$E$1144,2,FALSE),"")&" "&IFERROR(VLOOKUP(MID(H31,1,4),PIRA!$B$1:$E$1144,2,FALSE),"")&" "&IFERROR(VLOOKUP(MID(I31,1,4),PIRA!$B$1:$E$1144,2,FALSE),"") | H31: =IFERROR(IF(VLOOKUP(G31,Demos!$B$3:$K$1368,2,FALSE)=0,"",VLOOKUP(G31,Demos!$B$3:$K$1368,2,FALSE)),"") | I31: =IFERROR(IF(VLOOKUP(G31,Demos!$B$3:$K$1368,3,FALSE)=0,"",VLOOKUP(G31,Demos!$B$3:$K$1368,3,FALSE)),"") | J31: =IFERROR(IF(VLOOKUP(G31,Demos!$B$3:$K$1368,4,FALSE)=0,"",VLOOKUP(G31,Demos!$B$3:$K$1368,4,FALSE)),"") | K31: Martin Rohde | M31: 45410 | N31: =IFERROR(VLOOKUP(G31,Demos!$B$3:$K$1368,5,FALSE),"") | O31: =IF(N31="","",COUNTIF($N$6:N2150, N31)) | P31: =IFERROR(IF(VLOOKUP(G31,Demos!$B$3:$K$1368,6,FALSE)=0,"",VLOOKUP(G31,Demos!$B$3:$K$1368,6,FALSE)),"") | Q31: =IFERROR(IF(VLOOKUP(G31,Demos!$B$3:$K$1368,8,FALSE)=0,"",VLOOKUP(G31,Demos!$B$3:$K$1368,8,FALSE)),"") | R31: =IFERROR(IF(VLOOKUP(G31,Demos!$B$3:$K$1368,7,FALSE)=0,"",VLOOKUP(G31,Demos!$B$3:$K$1368,7,FALSE)),"") | T31: No (no setup done) | U31: =IFERROR(VLOOKUP(G31,Demos!$B$7:N5923,12,FALSE),"")
A32: =ROW()-5 -> 27 | B32: TN2785 | C32: =IFERROR(VLOOKUP(B32, Courses!$C$3:$E$836, 2, FALSE),"") -> Physical Transport Phenomena | D32: =IFERROR(VLOOKUP(MID(G32,1,1), PIRA!$B$1:$E$1146, 2, FALSE),"") | E32: =IFERROR(VLOOKUP(MID(G32,1,2),PIRA!$B$1:$E$1144,2,FALSE),"")&" "&IFERROR(VLOOKUP(MID(H32,1,2),PIRA!$B$1:$E$1144,2,FALSE),"")&" "&IFERROR(VLOOKUP(MID(I32,1,2),PIRA!$B$1:$E$1144,2,FALSE),"") | F32: =IFERROR(VLOOKUP(MID(G32,1,4),PIRA!$B$1:$E$1144,2,FALSE),"")&" "&IFERROR(VLOOKUP(MID(H32,1,4),PIRA!$B$1:$E$1144,2,FALSE),"")&" "&IFERROR(VLOOKUP(MID(I32,1,4),PIRA!$B$1:$E$1144,2,FALSE),"") | H32: =IFERROR(IF(VLOOKUP(G32,Demos!$B$3:$K$1368,2,FALSE)=0,"",VLOOKUP(G32,Demos!$B$3:$K$1368,2,FALSE)),"") | I32: =IFERROR(IF(VLOOKUP(G32,Demos!$B$3:$K$1368,3,FALSE)=0,"",VLOOKUP(G32,Demos!$B$3:$K$1368,3,FALSE)),"") | J32: =IFERROR(IF(VLOOKUP(G32,Demos!$B$3:$K$1368,4,FALSE)=0,"",VLOOKUP(G32,Demos!$B$3:$K$1368,4,FALSE)),"") | K32: Martin Rohde | M32: 45410 | N32: =IFERROR(VLOOKUP(G32,Demos!$B$3:$K$1368,5,FALSE),"") | O32: =IF(N32="","",COUNTIF($N$6:N2151, N32)) | P32: =IFERROR(IF(VLOOKUP(G32,Demos!$B$3:$K$1368,6,FALSE)=0,"",VLOOKUP(G32,Demos!$B$3:$K$1368,6,FALSE)),"") | Q32: =IFERROR(IF(VLOOKUP(G32,Demos!$B$3:$K$1368,8,FALSE)=0,"",VLOOKUP(G32,Demos!$B$3:$K$1368,8,FALSE)),"") | R32: =IFERROR(IF(VLOOKUP(G32,Demos!$B$3:$K$1368,7,FALSE)=0,"",VLOOKUP(G32,Demos!$B$3:$K$1368,7,FALSE)),"") | T32: No (no setup done) | U32: =IFERROR(VLOOKUP(G32,Demos!$B$7:N5924,12,FALSE),"")
A33: =ROW()-5 -> 28 | B33: TN2785 | C33: =IFERROR(VLOOKUP(B33, Courses!$C$3:$E$836, 2, FALSE),"") -> Physical Transport Phenomena | D33: =IFERROR(VLOOKUP(MID(G33,1,1), PIRA!$B$1:$E$1146, 2, FALSE),"") | E33: =IFERROR(VLOOKUP(MID(G33,1,2),PIRA!$B$1:$E$1144,2,FALSE),"")&" "&IFERROR(VLOOKUP(MID(H33,1,2),PIRA!$B$1:$E$1144,2,FALSE),"")&" "&IFERROR(VLOOKUP(MID(I33,1,2),PIRA!$B$1:$E$1144,2,FALSE),"") | F33: =IFERROR(VLOOKUP(MID(G33,1,4),PIRA!$B$1:$E$1144,2,FALSE),"")&" "&IFERROR(VLOOKUP(MID(H33,1,4),PIRA!$B$1:$E$1144,2,FALSE),"")&" "&IFERROR(VLOOKUP(MID(I33,1,4),PIRA!$B$1:$E$1144,2,FALSE),"") | H33: =IFERROR(IF(VLOOKUP(G33,Demos!$B$3:$K$1368,2,FALSE)=0,"",VLOOKUP(G33,Demos!$B$3:$K$1368,2,FALSE)),"") | I33: =IFERROR(IF(VLOOKUP(G33,Demos!$B$3:$K$1368,3,FALSE)=0,"",VLOOKUP(G33,Demos!$B$3:$K$1368,3,FALSE)),"") | J33: =IFERROR(IF(VLOOKUP(G33,Demos!$B$3:$K$1368,4,FALSE)=0,"",VLOOKUP(G33,Demos!$B$3:$K$1368,4,FALSE)),"") | K33: Martin Rohde | M33: 45410 | N33: =IFERROR(VLOOKUP(G33,Demos!$B$3:$K$1368,5,FALSE),"") | O33: =IF(N33="","",COUNTIF($N$6:N2152, N33)) | P33: =IFERROR(IF(VLOOKUP(G33,Demos!$B$3:$K$1368,6,FALSE)=0,"",VLOOKUP(G33,Demos!$B$3:$K$1368,6,FALSE)),"") | Q33: =IFERROR(IF(VLOOKUP(G33,Demos!$B$3:$K$1368,8,FALSE)=0,"",VLOOKUP(G33,Demos!$B$3:$K$1368,8,FALSE)),"") | R33: =IFERROR(IF(VLOOKUP(G33,Demos!$B$3:$K$1368,7,FALSE)=0,"",VLOOKUP(G33,Demos!$B$3:$K$1368,7,FALSE)),"") | T33: No (no setup done) | U33: =IFERROR(VLOOKUP(G33,Demos!$B$7:N5925,12,FALSE),"")
A34: =ROW()-5 -> 29 | B34: TN2785 | C34: =IFERROR(VLOOKUP(B34, Courses!$C$3:$E$836, 2, FALSE),"") -> Physical Transport Phenomena | D34: =IFERROR(VLOOKUP(MID(G34,1,1), PIRA!$B$1:$E$1146, 2, FALSE),"") | E34: =IFERROR(VLOOKUP(MID(G34,1,2),PIRA!$B$1:$E$1144,2,FALSE),"")&" "&IFERROR(VLOOKUP(MID(H34,1,2),PIRA!$B$1:$E$1144,2,FALSE),"")&" "&IFERROR(VLOOKUP(MID(I34,1,2),PIRA!$B$1:$E$1144,2,FALSE),"") | F34: =IFERROR(VLOOKUP(MID(G34,1,4),PIRA!$B$1:$E$1144,2,FALSE),"")&" "&IFERROR(VLOOKUP(MID(H34,1,4),PIRA!$B$1:$E$1144,2,FALSE),"")&" "&IFERROR(VLOOKUP(MID(I34,1,4),PIRA!$B$1:$E$1144,2,FALSE),"") | H34: =IFERROR(IF(VLOOKUP(G34,Demos!$B$3:$K$1368,2,FALSE)=0,"",VLOOKUP(G34,Demos!$B$3:$K$1368,2,FALSE)),"") | I34: =IFERROR(IF(VLOOKUP(G34,Demos!$B$3:$K$1368,3,FALSE)=0,"",VLOOKUP(G34,Demos!$B$3:$K$1368,3,FALSE)),"") | J34: =IFERROR(IF(VLOOKUP(G34,Demos!$B$3:$K$1368,4,FALSE)=0,"",VLOOKUP(G34,Demos!$B$3:$K$1368,4,FALSE)),"") | K34: Martin Rohde | M34: 45410 | N34: =IFERROR(VLOOKUP(G34,Demos!$B$3:$K$1368,5,FALSE),"") | O34: =IF(N34="","",COUNTIF($N$6:N2153, N34)) | P34: =IFERROR(IF(VLOOKUP(G34,Demos!$B$3:$K$1368,6,FALSE)=0,"",VLOOKUP(G34,Demos!$B$3:$K$1368,6,FALSE)),"") | Q34: =IFERROR(IF(VLOOKUP(G34,Demos!$B$3:$K$1368,8,FALSE)=0,"",VLOOKUP(G34,Demos!$B$3:$K$1368,8,FALSE)),"") | R34: =IFERROR(IF(VLOOKUP(G34,Demos!$B$3:$K$1368,7,FALSE)=0,"",VLOOKUP(G34,Demos!$B$3:$K$1368,7,FALSE)),"") | T34: No (lecturer decided not to use demo) | U34: =IFERROR(VLOOKUP(G34,Demos!$B$7:N5926,12,FALSE),"")
A35: =ROW()-5 -> 30 | B35: TN2785 | C35: =IFERROR(VLOOKUP(B35, Courses!$C$3:$E$836, 2, FALSE),"") -> Physical Transport Phenomena | D35: =IFERROR(VLOOKUP(MID(G35,1,1), PIRA!$B$1:$E$1146, 2, FALSE),"") -> 2 Fluid Mechanics | E35: =IFERROR(VLOOKUP(MID(G35,1,2),PIRA!$B$1:$E$1144,2,FALSE),"")&" "&IFERROR(VLOOKUP(MID(H35,1,2),PIRA!$B$1:$E$1144,2,FALSE),"")&" "&IFERROR(VLOOKUP(MID(I35,1,2),PIRA!$B$1:$E$1144,2,FALSE),"") -> Dynamics of Fluids | F35: =IFERROR(VLOOKUP(MID(G35,1,4),PIRA!$B$1:$E$1144,2,FALSE),"")&" "&IFERROR(VLOOKUP(MID(H35,1,4),PIRA!$B$1:$E$1144,2,FALSE),"")&" "&IFERROR(VLOOKUP(MID(I35,1,4),PIRA!$B$1:$E$1144,2,FALSE),"") -> Forces in Moving Fluids | G35: 2C20.30 | H35: =IFERROR(IF(VLOOKUP(G35,Demos!$B$3:$K$1368,2,FALSE)=0,"",VLOOKUP(G35,Demos!$B$3:$K$1368,2,FALSE)),"") | I35: =IFERROR(IF(VLOOKUP(G35,Demos!$B$3:$K$1368,3,FALSE)=0,"",VLOOKUP(G35,Demos!$B$3:$K$1368,3,FALSE)),"") | J35: =IFERROR(IF(VLOOKUP(G35,Demos!$B$3:$K$1368,4,FALSE)=0,"",VLOOKUP(G35,Demos!$B$3:$K$1368,4,FALSE)),"") | K35: Chris Klein | L35: Martin Rohde | M35: 45408 | N35: =IFERROR(VLOOKUP(G35,Demos!$B$3:$K$1368,5,FALSE),"") -> Vacuum Cleaner and Ping-Pong Ball | O35: =IF(N35="","",COUNTIF($N$6:N2154, N35)) -> 20 | P35: =IFERROR(IF(VLOOKUP(G35,Demos!$B$3:$K$1368,6,FALSE)=0,"",VLOOKUP(G35,Demos!$B$3:$K$1368,6,FALSE)),"") -> N/A | Q35: =IFERROR(IF(VLOOKUP(G35,Demos!$B$3:$K$1368,8,FALSE)=0,"",VLOOKUP(G35,Demos!$B$3:$K$1368,8,FALSE)),"") | R35: =IFERROR(IF(VLOOKUP(G35,Demos!$B$3:$K$1368,7,FALSE)=0,"",VLOOKUP(G35,Demos!$B$3:$K$1368,7,FALSE)),"") -> See 2021 Zoomopname "opname hoorcollege 2.mp4" and Collegerama recording 2011/2012 - https://collegerama.tudelft.nl/Mediasite/Channel/as-bsc-tn/watch/b6b2331bc2144aba9c70d01fb3cfa6311d and 2022-2023 from 01:25:40 https://collegerama.tudelft.nl/Mediasite/Channel/as-bsc-tn/watch/2f27d3d6436b4dc9b44a4a21e91f98331d | U35: =IFERROR(VLOOKUP(G35,Demos!$B$7:N5930,12,FALSE),"")
A36: =ROW()-5 -> 31 | B36: TN2421 | C36: =IFERROR(VLOOKUP(B36, Courses!$C$3:$E$836, 2, FALSE),"") -> Optics | D36: =IFERROR(VLOOKUP(MID(G36,1,1), PIRA!$B$1:$E$1146, 2, FALSE),"") -> 6 Optics | E36: =IFERROR(VLOOKUP(MID(G36,1,2),PIRA!$B$1:$E$1144,2,FALSE),"")&" "&IFERROR(VLOOKUP(MID(H36,1,2),PIRA!$B$1:$E$1144,2,FALSE),"")&" "&IFERROR(VLOOKUP(MID(I36,1,2),PIRA!$B$1:$E$1144,2,FALSE),"") -> Modern Optics | F36: =IFERROR(VLOOKUP(MID(G36,1,4),PIRA!$B$1:$E$1144,2,FALSE),"")&" "&IFERROR(VLOOKUP(MID(H36,1,4),PIRA!$B$1:$E$1144,2,FALSE),"")&" "&IFERROR(VLOOKUP(MID(I36,1,4),PIRA!$B$1:$E$1144,2,FALSE),"") -> Holography | G36: 6Q10.10 | H36: =IFERROR(IF(VLOOKUP(G36,Demos!$B$3:$K$1368,2,FALSE)=0,"",VLOOKUP(G36,Demos!$B$3:$K$1368,2,FALSE)),"") | I36: =IFERROR(IF(VLOOKUP(G36,Demos!$B$3:$K$1368,3,FALSE)=0,"",VLOOKUP(G36,Demos!$B$3:$K$1368,3,FALSE)),"") | J36: =IFERROR(IF(VLOOKUP(G36,Demos!$B$3:$K$1368,4,FALSE)=0,"",VLOOKUP(G36,Demos!$B$3:$K$1368,4,FALSE)),"") | K36: Aurele Adam | L36: Miriam Menzel | M36: 45396 | N36: =IFERROR(VLOOKUP(G36,Demos!$B$3:$K$1368,5,FALSE),"") -> Holography | O36: =IF(N36="","",COUNTIF($N$6:N2155, N36)) -> 2 | P36: =IFERROR(IF(VLOOKUP(G36,Demos!$B$3:$K$1368,6,FALSE)=0,"",VLOOKUP(G36,Demos!$B$3:$K$1368,6,FALSE)),"") -> N/A | Q36: =IFERROR(IF(VLOOKUP(G36,Demos!$B$3:$K$1368,8,FALSE)=0,"",VLOOKUP(G36,Demos!$B$3:$K$1368,8,FALSE)),"") -> Missing setup as of 26 Mar 2014 | R36: =IFERROR(IF(VLOOKUP(G36,Demos!$B$3:$K$1368,7,FALSE)=0,"",VLOOKUP(G36,Demos!$B$3:$K$1368,7,FALSE)),"") | U36: =IFERROR(VLOOKUP(G36,Demos!$B$7:N5882,12,FALSE),"")
A37: =ROW()-5 -> 32 | B37: TN2421 | C37: =IFERROR(VLOOKUP(B37, Courses!$C$3:$E$836, 2, FALSE),"") -> Optics | D37: =IFERROR(VLOOKUP(MID(G37,1,1), PIRA!$B$1:$E$1146, 2, FALSE),"") -> 6 Optics | E37: =IFERROR(VLOOKUP(MID(G37,1,2),PIRA!$B$1:$E$1144,2,FALSE),"")&" "&IFERROR(VLOOKUP(MID(H37,1,2),PIRA!$B$1:$E$1144,2,FALSE),"")&" "&IFERROR(VLOOKUP(MID(I37,1,2),PIRA!$B$1:$E$1144,2,FALSE),"") -> Diffraction | F37: =IFERROR(VLOOKUP(MID(G37,1,4),PIRA!$B$1:$E$1144,2,FALSE),"")&" "&IFERROR(VLOOKUP(MID(H37,1,4),PIRA!$B$1:$E$1144,2,FALSE),"")&" "&IFERROR(VLOOKUP(MID(I37,1,4),PIRA!$B$1:$E$1144,2,FALSE),"") -> Diffraction Around Objects | G37: 6C20.03 | H37: =IFERROR(IF(VLOOKUP(G37,Demos!$B$3:$K$1368,2,FALSE)=0,"",VLOOKUP(G37,Demos!$B$3:$K$1368,2,FALSE)),"") | I37: =IFERROR(IF(VLOOKUP(G37,Demos!$B$3:$K$1368,3,FALSE)=0,"",VLOOKUP(G37,Demos!$B$3:$K$1368,3,FALSE)),"") | J37: =IFERROR(IF(VLOOKUP(G37,Demos!$B$3:$K$1368,4,FALSE)=0,"",VLOOKUP(G37,Demos!$B$3:$K$1368,4,FALSE)),"") | K37: Miriam Menzel | L37: Aurele Adam | M37: 45394 | N37: =IFERROR(VLOOKUP(G37,Demos!$B$3:$K$1368,5,FALSE),"") -> Diffraction (2b), Single Slit | O37: =IF(N37="","",COUNTIF($N$6:N2156, N37)) -> 12 | P37: =IFERROR(IF(VLOOKUP(G37,Demos!$B$3:$K$1368,6,FALSE)=0,"",VLOOKUP(G37,Demos!$B$3:$K$1368,6,FALSE)),"") -> www.de-monstrare.nl/pdf/Diffraction_2b_,%20single%20slit.pdf | Q37: =IFERROR(IF(VLOOKUP(G37,Demos!$B$3:$K$1368,8,FALSE)=0,"",VLOOKUP(G37,Demos!$B$3:$K$1368,8,FALSE)),"") | R37: =IFERROR(IF(VLOOKUP(G37,Demos!$B$3:$K$1368,7,FALSE)=0,"",VLOOKUP(G37,Demos!$B$3:$K$1368,7,FALSE)),"") | U37: =IFERROR(VLOOKUP(G37,Demos!$B$7:N5933,12,FALSE),"")
A38: =ROW()-5 -> 33 | B38: TN2421 | C38: =IFERROR(VLOOKUP(B38, Courses!$C$3:$E$836, 2, FALSE),"") -> Optics | D38: =IFERROR(VLOOKUP(MID(G38,1,1), PIRA!$B$1:$E$1146, 2, FALSE),"") -> 6 Optics | E38: =IFERROR(VLOOKUP(MID(G38,1,2),PIRA!$B$1:$E$1144,2,FALSE),"")&" "&IFERROR(VLOOKUP(MID(H38,1,2),PIRA!$B$1:$E$1144,2,FALSE),"")&" "&IFERROR(VLOOKUP(MID(I38,1,2),PIRA!$B$1:$E$1144,2,FALSE),"") -> Interference Diffraction | F38: =IFERROR(VLOOKUP(MID(G38,1,4),PIRA!$B$1:$E$1144,2,FALSE),"")&" "&IFERROR(VLOOKUP(MID(H38,1,4),PIRA!$B$1:$E$1144,2,FALSE),"")&" "&IFERROR(VLOOKUP(MID(I38,1,4),PIRA!$B$1:$E$1144,2,FALSE),"") -> Interference From Two Sources Diffraction Through One Slit | G38: 6D10.10 | H38: =IFERROR(IF(VLOOKUP(G38,Demos!$B$3:$K$1368,2,FALSE)=0,"",VLOOKUP(G38,Demos!$B$3:$K$1368,2,FALSE)),"") -> 6C10.26 | I38: =IFERROR(IF(VLOOKUP(G38,Demos!$B$3:$K$1368,3,FALSE)=0,"",VLOOKUP(G38,Demos!$B$3:$K$1368,3,FALSE)),"") | J38: =IFERROR(IF(VLOOKUP(G38,Demos!$B$3:$K$1368,4,FALSE)=0,"",VLOOKUP(G38,Demos!$B$3:$K$1368,4,FALSE)),"") | K38: Miriam Menzel | L38: Aurele Adam | M38: 45394 | N38: =IFERROR(VLOOKUP(G38,Demos!$B$3:$K$1368,5,FALSE),"") -> Young's Double Slit | O38: =IF(N38="","",COUNTIF($N$6:N2157, N38)) -> 19 | P38: =IFERROR(IF(VLOOKUP(G38,Demos!$B$3:$K$1368,6,FALSE)=0,"",VLOOKUP(G38,Demos!$B$3:$K$1368,6,FALSE)),"") -> www.de-monstrare.nl/pdf/Young%27s%20double%20slit.pdf | Q38: =IFERROR(IF(VLOOKUP(G38,Demos!$B$3:$K$1368,8,FALSE)=0,"",VLOOKUP(G38,Demos!$B$3:$K$1368,8,FALSE)),"") -> Not in database yet | R38: =IFERROR(IF(VLOOKUP(G38,Demos!$B$3:$K$1368,7,FALSE)=0,"",VLOOKUP(G38,Demos!$B$3:$K$1368,7,FALSE)),"") -> See 09 Apr 2019 Collegerama recoring TN2421_10 from 01:29:55 - https://collegerama.tudelft.nl/Mediasite/Channel/as-bsc-tn/watch/a70c41f4099e41a3966d61dab00a21c61d | U38: =IFERROR(VLOOKUP(G38,Demos!$B$7:N5932,12,FALSE),"")
A39: =ROW()-5 -> 34 | B39: NB2041 | C39: =IFERROR(VLOOKUP(B39, Courses!$C$3:$E$836, 2, FALSE),"") -> Optics and Microscopy | D39: =IFERROR(VLOOKUP(MID(G39,1,1), PIRA!$B$1:$E$1146, 2, FALSE),"") -> 6 Optics | E39: =IFERROR(VLOOKUP(MID(G39,1,2),PIRA!$B$1:$E$1144,2,FALSE),"")&" "&IFERROR(VLOOKUP(MID(H39,1,2),PIRA!$B$1:$E$1144,2,FALSE),"")&" "&IFERROR(VLOOKUP(MID(I39,1,2),PIRA!$B$1:$E$1144,2,FALSE),"") -> Polarisation | F39: =IFERROR(VLOOKUP(MID(G39,1,4),PIRA!$B$1:$E$1144,2,FALSE),"")&" "&IFERROR(VLOOKUP(MID(H39,1,4),PIRA!$B$1:$E$1144,2,FALSE),"")&" "&IFERROR(VLOOKUP(MID(I39,1,4),PIRA!$B$1:$E$1144,2,FALSE),"") -> Birefringence | G39: 6H35.01 | H39: =IFERROR(IF(VLOOKUP(G39,Demos!$B$3:$K$1368,2,FALSE)=0,"",VLOOKUP(G39,Demos!$B$3:$K$1368,2,FALSE)),"") | I39: =IFERROR(IF(VLOOKUP(G39,Demos!$B$3:$K$1368,3,FALSE)=0,"",VLOOKUP(G39,Demos!$B$3:$K$1368,3,FALSE)),"") | J39: =IFERROR(IF(VLOOKUP(G39,Demos!$B$3:$K$1368,4,FALSE)=0,"",VLOOKUP(G39,Demos!$B$3:$K$1368,4,FALSE)),"") | K39: Elizabeth Carol | L39: Silvania Pereira | M39: 45390 | N39: =IFERROR(VLOOKUP(G39,Demos!$B$3:$K$1368,5,FALSE),"") -> Kaleidoscope | O39: =IF(N39="","",COUNTIF($N$6:N2158, N39)) -> 12 | P39: =IFERROR(IF(VLOOKUP(G39,Demos!$B$3:$K$1368,6,FALSE)=0,"",VLOOKUP(G39,Demos!$B$3:$K$1368,6,FALSE)),"") -> N/A | Q39: =IFERROR(IF(VLOOKUP(G39,Demos!$B$3:$K$1368,8,FALSE)=0,"",VLOOKUP(G39,Demos!$B$3:$K$1368,8,FALSE)),"") | R39: =IFERROR(IF(VLOOKUP(G39,Demos!$B$3:$K$1368,7,FALSE)=0,"",VLOOKUP(G39,Demos!$B$3:$K$1368,7,FALSE)),"") | T39: No (setup done) | U39: =IFERROR(VLOOKUP(G39,Demos!$B$7:N5931,12,FALSE),"")
A40: =ROW()-5 -> 35 | B40: TN2421 | C40: =IFERROR(VLOOKUP(B40, Courses!$C$3:$E$836, 2, FALSE),"") -> Optics | D40: =IFERROR(VLOOKUP(MID(G40,1,1), PIRA!$B$1:$E$1146, 2, FALSE),"") -> 6 Optics | E40: =IFERROR(VLOOKUP(MID(G40,1,2),PIRA!$B$1:$E$1144,2,FALSE),"")&" "&IFERROR(VLOOKUP(MID(H40,1,2),PIRA!$B$1:$E$1144,2,FALSE),"")&" "&IFERROR(VLOOKUP(MID(I40,1,2),PIRA!$B$1:$E$1144,2,FALSE),"") -> Diffraction Modern Optics Diffraction | F40: =IFERROR(VLOOKUP(MID(G40,1,4),PIRA!$B$1:$E$1144,2,FALSE),"")&" "&IFERROR(VLOOKUP(MID(H40,1,4),PIRA!$B$1:$E$1144,2,FALSE),"")&" "&IFERROR(VLOOKUP(MID(I40,1,4),PIRA!$B$1:$E$1144,2,FALSE),"") -> Diffraction Through One Slit Physical Optics Diffraction Around Objects | G40: 6C10.10 | H40: =IFERROR(IF(VLOOKUP(G40,Demos!$B$3:$K$1368,2,FALSE)=0,"",VLOOKUP(G40,Demos!$B$3:$K$1368,2,FALSE)),"") -> 6Q20.21 | I40: =IFERROR(IF(VLOOKUP(G40,Demos!$B$3:$K$1368,3,FALSE)=0,"",VLOOKUP(G40,Demos!$B$3:$K$1368,3,FALSE)),"") -> 6C20.18 | J40: =IFERROR(IF(VLOOKUP(G40,Demos!$B$3:$K$1368,4,FALSE)=0,"",VLOOKUP(G40,Demos!$B$3:$K$1368,4,FALSE)),"") | K40: Aurele Adam | L40: Miriam Menzel | M40: 45389 | N40: =IFERROR(VLOOKUP(G40,Demos!$B$3:$K$1368,5,FALSE),"") -> Fraunhofer and Fresnel Diffraction | O40: =IF(N40="","",COUNTIF($N$6:N2159, N40)) -> 4 | P40: =IFERROR(IF(VLOOKUP(G40,Demos!$B$3:$K$1368,6,FALSE)=0,"",VLOOKUP(G40,Demos!$B$3:$K$1368,6,FALSE)),"") -> www.de-monstrare.nl/pdf/Fraunhofer%20-%20and%20Fresnel%20diffraction.pdf | Q40: =IFERROR(IF(VLOOKUP(G40,Demos!$B$3:$K$1368,8,FALSE)=0,"",VLOOKUP(G40,Demos!$B$3:$K$1368,8,FALSE)),"") | R40: =IFERROR(IF(VLOOKUP(G40,Demos!$B$3:$K$1368,7,FALSE)=0,"",VLOOKUP(G40,Demos!$B$3:$K$1368,7,FALSE)),"") -> See 05 Apr 2019 Collegerama recording TN2421_09 from 01:23:38 - https://collegerama.tudelft.nl/Mediasite/Channel/as-bsc-tn/watch/556b44abfbb545d184afa87a44b212111d | T40: No (lack of time) | U40: =IFERROR(VLOOKUP(G40,Demos!$B$7:N5896,12,FALSE),"")
